Workbook

Sheet 00_작성안내
B1: 학생 역량 데이터 수집 템플릿
B4: 1. 시트 구성
B5: 00_작성안내 | C5: 이 시트
B6: 01_학생목록 | C6: 학사 명부(기준값)와 각 학생 시트를 대조하고 수집 완료율·⚠ 건수를 보여줌 (새 학생을 추가하면 여기에 한 줄 추가)
B7: 02_수집현황 | C7: 카테고리 34개 × 학생 데이터 상태 매트릭스 (자동 참조, 색으로 누락 확인)
B8: 10_빈양식 | C8: 실제 수집에 쓰는 빈 양식. 학생 1명당 이 시트를 복사해서 사용 (시트 이름 규칙: 학번_이름)
B9: 11_작성예시 | C9: 34개 카테고리를 모두 채운 기준 예시 — 형식이 헷갈릴 때 참고
B10: S01~S06 | C10: 입력 상태가 서로 다른 가상 학생 6명 (아래 3번 표) — 역량평가 프롬프트 테스트용
B11: 코드표 | C11: 데이터 상태 4종 정의와 모든 드롭다운 허용값 목록
B12: 데이터카테고리_마스터 / 대분류_요약 | C12: 원본 마스터(참고용, 수정하지 않음)
B14: 2. 입력 규칙
B15: 입력 칸 | C15: 연녹색 칸만 입력합니다. 회색 라벨·형식 줄·H열 자동점검은 건드리지 않습니다.
B16: 데이터 상태(필수) | C16: 카테고리마다 G열에서 값 있음 / 활동 없음 / 미수집 / 해당 없음 중 하나를 고릅니다. '활동 없음'은 0점, '미수집'은 계산 제외라서 결과가 크게 달라지므로 반드시 구분합니다. 자세한 정의는 코드표.
B17: 한 칸에 값 하나 | C17: 'TOEIC 850, OPIc IM2'처럼 한 칸에 여러 값을 넣지 말고 표의 행을 나눠 입력합니다.
B18: 숫자 | C18: 단위·기호 없이 숫자만 (850 ○ / 850점 ✕, 95 ○ / 95% ✕ / 0.95 ✕). 평점은 4.5 만점 기준 소수 2자리.
B19: 날짜 | C19: 연월은 YYYY-MM, 날짜는 YYYY-MM-DD, 학기는 YYYY-1 / YYYY-2 / YYYY-여름 / YYYY-겨울. 진행 중이면 종료 칸에 '진행중'.
B20: 기간 | C20: 개월 수(숫자)로 적습니다. 해외경험만 주 단위입니다.
B21: 목록 항목 | C21: 드롭다운에 없는 값은 입력되지 않습니다. 맞는 값이 없으면 가장 가까운 값을 고르고 비고·서술 칸에 설명합니다.
B22: 행이 부족할 때 | C22: 표 안쪽(마지막 입력 행 위)에 행을 삽입하면 자동점검 범위와 서식이 함께 늘어납니다.
B23: 부분 누락 | C23: 상태가 '값 있음'인 카테고리에서 일부 칸만 비면 그 칸만 미수집으로 봅니다 (예: 출석률만 있고 퀴즈 횟수는 빈칸).
B24: 자동점검(H열) | C24: ✓ 정상 / ⚠ 값 있음인데 입력값 없음 / ⚠ 상태와 입력값 불일치 / ⚠ 상태 미선택(입력값 있음) / 상태 미선택 → 미수집 간주
B25: STAR 기록(33번) | C25: 상황·과제·행동·결과를 각 칸에 나눠 적고, 결과에는 가능한 한 수치를 넣습니다. 정성 루브릭의 핵심 근거입니다.
B27: 3. 샘플 학생 6명 설계 (모두 가상 데이터)
B28: 시트 / 유형 | C28: 입력 상태와 평가 테스트 포인트
B29: 11_작성예시 완전 작성 예시 | C29: 34개 카테고리 전부 '값 있음' — 입력 형식의 기준 예시
B30: S01_김민준 충실형 | C30: 대부분 값 있음 + 일부 '활동 없음'(창업·특허·해외) → 높은 충족도, 활동 없음은 0점 처리되는지 확인
B31: S02_이서연 일부 누락형 | C31: LMS·진단·동료평가 등 시스템 항목이 '미수집' + 공학인증 '해당 없음' → 미수집이 0점 처리되지 않는지, 해당 역량 충족도가 낮아지는지 확인
B32: S03_박지호 정보 적은 신입생형 | C32: 1학기만 이수, 대부분 '활동 없음' → 학년 보정(이수 1학기)이 적용되는지, 어학 '미수집'과 자격증 '활동 없음'이 다르게 처리되는지 확인
B33: S04_최유진 다수 누락형 | C33: 성적·수강·3품·비교과만 있고 나머지 대부분 미수집(일부는 상태조차 미선택) → 대부분 역량 '판정 보류'가 나와야 정상
B34: S05_정하늘 비정형·오류 입력형 | C34: 자유서술·단위 포함·날짜형식 혼재·한 칸 여러 값·상태-값 불일치 → 파싱 규칙과 ⚠ 자동점검이 잡아내는지 확인
B35: S06_한도윤 편입·편중형 + 기본정보 불일치 | C35: 편입 후 본교 1학기, 글로벌·어학 데이터만 풍부, 시트 학년(4)≠학사 명부(3) → '데이터 불일치 경고'와 편입생 공학인증 '해당 없음' 처리 확인
B37: 4. 색 범례
B38: 입력 칸 | C38: 직접 입력하는 칸
B39: 기존 항목(블록 머리) | C39: 블록 머리 색은 마스터 시트의 확보 구분 색과 같습니다.
B40: SKKU 확보가능(블록 머리) | C40: 블록 머리 색은 마스터 시트의 확보 구분 색과 같습니다.
B41: 추가 제안(블록 머리) | C41: 블록 머리 색은 마스터 시트의 확보 구분 색과 같습니다.

Sheet 01_학생목록
A1: 학생 목록 — 학사 명부와 수집 시트 대조 · 수집 현황 요약
A2: D~I열(학사 명부)은 학사시스템에서 받은 기준값이고, J~K열은 각 학생 시트에 입력된 값입니다. 두 값이 다르면 L열에 ⚠가 뜨며, 평가 시 '데이터 불일치 경고'로 처리합니다. M~S열은 02_수집현황에서 자동 집계됩니다.
A4: 샘플 정보 | D4: 학사 명부(기준값) | J4: 시트 입력값 대조 | M4: 수집 현황(자동)
A5: 구분 | B5: 시트명 | C5: 샘플 유형 | D5: 학번 | E5: 이름 | F5: 소속 대학 | G5: 전공 | H5: 학년 | I5: 학적 | J5: 시트 학번 | K5: 시트 학년 | L5: 기본정보 일치 | M5: 값 있음 | N5: 활동 없음 | O5: 해당 없음 | P5: 미수집(+미선택) | Q5: 수집 완료율 | R5: ⚠ 점검 | S5: 평가 테스트 포인트
A6: 예시 | B6: 11_작성예시 | C6: 완전 작성 예시 | D6: 2023313001 | E6: 김예시 | F6: 공과대학 | G6: 시스템경영공학과 | H6: 4 | I6: 학부 | J6: ='11_작성예시'!C7 -> 2023313001 | K6: ='11_작성예시'!C11 -> 4 | L6: =IF(AND(J6&""=D6&"",K6&""=H6&""),"✓ 일치","⚠ 불일치") -> ✓ 일치 | M6: ='02_수집현황'!E41 -> 34 | N6: ='02_수집현황'!E42 -> 0 | O6: ='02_수집현황'!E43 -> 0 | P6: ='02_수집현황'!E44+'02_수집현황'!E45 -> 0 | Q6: ='02_수집현황'!E46 -> 1 | R6: ='02_수집현황'!E47 -> 0 | S6: 34개 카테고리 전부 '값 있음' — 입력 형식의 기준 예시
A7: S01 | B7: S01_김민준 | C7: 충실형 | D7: 2023310452 | E7: 김민준 | F7: 공과대학 | G7: 기계공학부 | H7: 4 | I7: 학부 | J7: ='S01_김민준'!C7 -> 2023310452 | K7: ='S01_김민준'!C11 -> 4 | L7: =IF(AND(J7&""=D7&"",K7&""=H7&""),"✓ 일치","⚠ 불일치") -> ✓ 일치 | M7: ='02_수집현황'!F41 -> 28 | N7: ='02_수집현황'!F42 -> 5 | O7: ='02_수집현황'!F43 -> 0 | P7: ='02_수집현황'!F44+'02_수집현황'!F45 -> 1 | Q7: ='02_수집현황'!F46 -> 0.97058824 | R7: ='02_수집현황'!F47 -> 0 | S7: 대부분 값 있음 + 일부 '활동 없음'(창업·특허·해외) → 높은 충족도, 활동 없음은 0점 처리되는지 확인
A8: S02 | B8: S02_이서연 | C8: 일부 누락형 | D8: 2024311187 | E8: 이서연 | F8: 경영대학 | G8: 경영학과 | H8: 3 | I8: 학부 | J8: ='S02_이서연'!C7 -> 2024311187 | K8: ='S02_이서연'!C11 -> 3 | L8: =IF(AND(J8&""=D8&"",K8&""=H8&""),"✓ 일치","⚠ 불일치") -> ✓ 일치 | M8: ='02_수집현황'!G41 -> 17 | N8: ='02_수집현황'!G42 -> 9 | O8: ='02_수집현황'!G43 -> 1 | P8: ='02_수집현황'!G44+'02_수집현황'!G45 -> 7 | Q8: ='02_수집현황'!G46 -> 0.79411765 | R8: ='02_수집현황'!G47 -> 0 | S8: LMS·진단·동료평가 등 시스템 항목이 '미수집' + 공학인증 '해당 없음' → 미수집이 0점 처리되지 않는지, 해당 역량 충족도가 낮아지는지 확인
A9: S03 | B9: S03_박지호 | C9: 정보 적은 신입생형 | D9: 2026312045 | E9: 박지호 | F9: 소프트웨어융합대학 | G9: 소프트웨어학과 | H9: 1 | I9: 학부 | J9: ='S03_박지호'!C7 -> 2026312045 | K9: ='S03_박지호'!C11 -> 1 | L9: =IF(AND(J9&""=D9&"",K9&""=H9&""),"✓ 일치","⚠ 불일치") -> ✓ 일치 | M9: ='02_수집현황'!H41 -> 18 | N9: ='02_수집현황'!H42 -> 14 | O9: ='02_수집현황'!H43 -> 0 | P9: ='02_수집현황'!H44+'02_수집현황'!H45 -> 2 | Q9: ='02_수집현황'!H46 -> 0.94117647 | R9: ='02_수집현황'!H47 -> 0 | S9: 1학기만 이수, 대부분 '활동 없음' → 학년 보정(이수 1학기)이 적용되는지, 어학 '미수집'과 자격증 '활동 없음'이 다르게 처리되는지 확인
A10: S04 | B10: S04_최유진 | C10: 다수 누락형 | D10: 2022315533 | E10: 최유진 | F10: 사회과학대학 | G10: 사회학과 | H10: 4 | I10: 학부 | J10: ='S04_최유진'!C7 -> 2022315533 | K10: ='S04_최유진'!C11 -> 4 | L10: =IF(AND(J10&""=D10&"",K10&""=H10&""),"✓ 일치","⚠ 불일치") -> ✓ 일치 | M10: ='02_수집현황'!I41 -> 5 | N10: ='02_수집현황'!I42 -> 0 | O10: ='02_수집현황'!I43 -> 1 | P10: ='02_수집현황'!I44+'02_수집현황'!I45 -> 28 | Q10: ='02_수집현황'!I46 -> 0.17647059 | R10: ='02_수집현황'!I47 -> 0 | S10: 성적·수강·3품·비교과만 있고 나머지 대부분 미수집(일부는 상태조차 미선택) → 대부분 역량 '판정 보류'가 나와야 정상
A11: S05 | B11: S05_정하늘 | C11: 비정형·오류 입력형 | D11: 2025316290 | E11: 정하늘 | F11: 경제대학 | G11: 글로벌경제학과 | H11: 2 | I11: 학부 | J11: ='S05_정하늘'!C7 -> 2025316290 | K11: ='S05_정하늘'!C11 -> 2학년 | L11: =IF(AND(J11&""=D11&"",K11&""=H11&""),"✓ 일치","⚠ 불일치") -> ⚠ 불일치 | M11: ='02_수집현황'!J41 -> 19 | N11: ='02_수집현황'!J42 -> 9 | O11: ='02_수집현황'!J43 -> 0 | P11: ='02_수집현황'!J44+'02_수집현황'!J45 -> 6 | Q11: ='02_수집현황'!J46 -> 0.82352941 | R11: ='02_수집현황'!J47 -> 3 | S11: 자유서술·단위 포함·날짜형식 혼재·한 칸 여러 값·상태-값 불일치 → 파싱 규칙과 ⚠ 자동점검이 잡아내는지 확인
A12: S06 | B12: S06_한도윤 | C12: 편입·편중형 + 기본정보 불일치 | D12: 2026317702 | E12: 한도윤 | F12: 공과대학 | G12: 화학공학부 | H12: 3 | I12: 학부 | J12: ='S06_한도윤'!C7 -> 2026317702 | K12: ='S06_한도윤'!C11 -> 4 | L12: =IF(AND(J12&""=D12&"",K12&""=H12&""),"✓ 일치","⚠ 불일치") -> ⚠ 불일치 | M12: ='02_수집현황'!K41 -> 17 | N12: ='02_수집현황'!K42 -> 12 | O12: ='02_수집현황'!K43 -> 1 | P12: ='02_수집현황'!K44+'02_수집현황'!K45 -> 4 | Q12: ='02_수집현황'!K46 -> 0.88235294 | R12: ='02_수집현황'!K47 -> 0 | S12: 편입 후 본교 1학기, 글로벌·어학 데이터만 풍부, 시트 학년(4)≠학사 명부(3) → '데이터 불일치 경고'와 편입생 공학인증 '해당 없음' 처리 확인

Sheet 02_수집현황
A1: 수집현황 매트릭스 — 카테고리 × 학생 데이터 상태 (각 시트 G열 상태를 자동 참조)
A2: 미선택 = 상태를 고르지 않은 칸(미수집으로 간주). 아래 집계표는 01_학생목록에서 참조합니다.
A4: 대분류 | B4: No | C4: 카테고리 | D4: 확보 구분 | E4: 예시 | F4: S01 | G4: S02 | H4: S03 | I4: S04 | J4: S05 | K4: S06
E5: 김예시 | F5: 김민준 | G5: 이서연 | H5: 박지호 | I5: 최유진 | J5: 정하늘 | K5: 한도윤
A6: 학업·교과 | B6: 1 | C6: 성적데이터(전공·학기별) | D6: 기존 + SKKU 확보가능 | E6: =IF('11_작성예시'!G23="","미선택",'11_작성예시'!G23) -> 값 있음 | F6: =IF('S01_김민준'!G23="","미선택",'S01_김민준'!G23) -> 값 있음 | G6: =IF('S02_이서연'!G23="","미선택",'S02_이서연'!G23) -> 값 있음 | H6: =IF('S03_박지호'!G23="","미선택",'S03_박지호'!G23) -> 값 있음 | I6: =IF('S04_최유진'!G23="","미선택",'S04_최유진'!G23) -> 값 있음 | J6: =IF('S05_정하늘'!G23="","미선택",'S05_정하늘'!G23) -> 값 있음 | K6: =IF('S06_한도윤'!G23="","미선택",'S06_한도윤'!G23) -> 값 있음
A7: 학업·교과 | B7: 2 | C7: 수업유형별 성적 | D7: 기존 | E7: =IF('11_작성예시'!G39="","미선택",'11_작성예시'!G39) -> 값 있음 | F7: =IF('S01_김민준'!G39="","미선택",'S01_김민준'!G39) -> 값 있음 | G7: =IF('S02_이서연'!G39="","미선택",'S02_이서연'!G39) -> 값 있음 | H7: =IF('S03_박지호'!G39="","미선택",'S03_박지호'!G39) -> 값 있음 | I7: =IF('S04_최유진'!G39="","미선택",'S04_최유진'!G39) -> 미선택 | J7: =IF('S05_정하늘'!G39="","미선택",'S05_정하늘'!G39) -> 값 있음 | K7: =IF('S06_한도윤'!G39="","미선택",'S06_한도윤'!G39) -> 값 있음
A8: 학업·교과 | B8: 3 | C8: 수강과목·심화·융합 이수 | D8: 기존 + SKKU 확보가능 | E8: =IF('11_작성예시'!G49="","미선택",'11_작성예시'!G49) -> 값 있음 | F8: =IF('S01_김민준'!G49="","미선택",'S01_김민준'!G49) -> 값 있음 | G8: =IF('S02_이서연'!G49="","미선택",'S02_이서연'!G49) -> 값 있음 | H8: =IF('S03_박지호'!G49="","미선택",'S03_박지호'!G49) -> 값 있음 | I8: =IF('S04_최유진'!G49="","미선택",'S04_최유진'!G49) -> 값 있음 | J8: =IF('S05_정하늘'!G49="","미선택",'S05_정하늘'!G49) -> 값 있음 | K8: =IF('S06_한도윤'!G49="","미선택",'S06_한도윤'!G49) -> 값 있음
A9: 학업·교과 | B9: 4 | C9: 공학인증 | D9: SKKU 확보가능 | E9: =IF('11_작성예시'!G60="","미선택",'11_작성예시'!G60) -> 값 있음 | F9: =IF('S01_김민준'!G60="","미선택",'S01_김민준'!G60) -> 값 있음 | G9: =IF('S02_이서연'!G60="","미선택",'S02_이서연'!G60) -> 해당 없음 | H9: =IF('S03_박지호'!G60="","미선택",'S03_박지호'!G60) -> 값 있음 | I9: =IF('S04_최유진'!G60="","미선택",'S04_최유진'!G60) -> 해당 없음 | J9: =IF('S05_정하늘'!G60="","미선택",'S05_정하늘'!G60) -> 미선택 | K9: =IF('S06_한도윤'!G60="","미선택",'S06_한도윤'!G60) -> 해당 없음
A10: 학습행동(LMS) | B10: 5 | C10: LMS 학습데이터 | D10: 기존 | E10: =IF('11_작성예시'!G67="","미선택",'11_작성예시'!G67) -> 값 있음 | F10: =IF('S01_김민준'!G67="","미선택",'S01_김민준'!G67) -> 값 있음 | G10: =IF('S02_이서연'!G67="","미선택",'S02_이서연'!G67) -> 미수집 | H10: =IF('S03_박지호'!G67="","미선택",'S03_박지호'!G67) -> 값 있음 | I10: =IF('S04_최유진'!G67="","미선택",'S04_최유진'!G67) -> 값 있음 | J10: =IF('S05_정하늘'!G67="","미선택",'S05_정하늘'!G67) -> 값 있음 | K10: =IF('S06_한도윤'!G67="","미선택",'S06_한도윤'!G67) -> 값 있음
A11: 학습행동(LMS) | B11: 6 | C11: 교수면담·학업상담 | D11: 기존 | E11: =IF('11_작성예시'!G76="","미선택",'11_작성예시'!G76) -> 값 있음 | F11: =IF('S01_김민준'!G76="","미선택",'S01_김민준'!G76) -> 값 있음 | G11: =IF('S02_이서연'!G76="","미선택",'S02_이서연'!G76) -> 미수집 | H11: =IF('S03_박지호'!G76="","미선택",'S03_박지호'!G76) -> 값 있음 | I11: =IF('S04_최유진'!G76="","미선택",'S04_최유진'!G76) -> 미수집 | J11: =IF('S05_정하늘'!G76="","미선택",'S05_정하늘'!G76) -> 값 있음 | K11: =IF('S06_한도윤'!G76="","미선택",'S06_한도윤'!G76) -> 값 있음
A12: 학습행동(LMS) | B12: 7 | C12: 토론·게시판 참여 | D12: 추가 제안 | E12: =IF('11_작성예시'!G83="","미선택",'11_작성예시'!G83) -> 값 있음 | F12: =IF('S01_김민준'!G83="","미선택",'S01_김민준'!G83) -> 값 있음 | G12: =IF('S02_이서연'!G83="","미선택",'S02_이서연'!G83) -> 미수집 | H12: =IF('S03_박지호'!G83="","미선택",'S03_박지호'!G83) -> 값 있음 | I12: =IF('S04_최유진'!G83="","미선택",'S04_최유진'!G83) -> 미수집 | J12: =IF('S05_정하늘'!G83="","미선택",'S05_정하늘'!G83) -> 미선택 | K12: =IF('S06_한도윤'!G83="","미선택",'S06_한도윤'!G83) -> 값 있음
A13: 연구·학술 | B13: 8 | C13: 학회·연구활동 | D13: 기존 + SKKU 확보가능 | E13: =IF('11_작성예시'!G91="","미선택",'11_작성예시'!G91) -> 값 있음 | F13: =IF('S01_김민준'!G91="","미선택",'S01_김민준'!G91) -> 값 있음 | G13: =IF('S02_이서연'!G91="","미선택",'S02_이서연'!G91) -> 활동 없음 | H13: =IF('S03_박지호'!G91="","미선택",'S03_박지호'!G91) -> 활동 없음 | I13: =IF('S04_최유진'!G91="","미선택",'S04_최유진'!G91) -> 미수집 | J13: =IF('S05_정하늘'!G91="","미선택",'S05_정하늘'!G91) -> 활동 없음 | K13: =IF('S06_한도윤'!G91="","미선택",'S06_한도윤'!G91) -> 활동 없음
A14: 연구·학술 | B14: 9 | C14: 정보탐색 결과물(논문·보고서) | D14: 기존 | E14: =IF('11_작성예시'!G100="","미선택",'11_작성예시'!G100) -> 값 있음 | F14: =IF('S01_김민준'!G100="","미선택",'S01_김민준'!G100) -> 값 있음 | G14: =IF('S02_이서연'!G100="","미선택",'S02_이서연'!G100) -> 활동 없음 | H14: =IF('S03_박지호'!G100="","미선택",'S03_박지호'!G100) -> 활동 없음 | I14: =IF('S04_최유진'!G100="","미선택",'S04_최유진'!G100) -> 미수집 | J14: =IF('S05_정하늘'!G100="","미선택",'S05_정하늘'!G100) -> 활동 없음 | K14: =IF('S06_한도윤'!G100="","미선택",'S06_한도윤'!G100) -> 활동 없음
A15: 연구·학술 | B15: 10 | C15: TA 활동 | D15: SKKU 확보가능 | E15: =IF('11_작성예시'!G108="","미선택",'11_작성예시'!G108) -> 값 있음 | F15: =IF('S01_김민준'!G108="","미선택",'S01_김민준'!G108) -> 활동 없음 | G15: =IF('S02_이서연'!G108="","미선택",'S02_이서연'!G108) -> 활동 없음 | H15: =IF('S03_박지호'!G108="","미선택",'S03_박지호'!G108) -> 활동 없음 | I15: =IF('S04_최유진'!G108="","미선택",'S04_최유진'!G108) -> 미선택 | J15: =IF('S05_정하늘'!G108="","미선택",'S05_정하늘'!G108) -> 활동 없음 | K15: =IF('S06_한도윤'!G108="","미선택",'S06_한도윤'!G108) -> 활동 없음
A16: 실무·진로 | B16: 11 | C16: 인턴·현장실습 | D16: 기존 + SKKU 확보가능 | E16: =IF('11_작성예시'!G117="","미선택",'11_작성예시'!G117) -> 값 있음 | F16: =IF('S01_김민준'!G117="","미선택",'S01_김민준'!G117) -> 값 있음 | G16: =IF('S02_이서연'!G117="","미선택",'S02_이서연'!G117) -> 값 있음 | H16: =IF('S03_박지호'!G117="","미선택",'S03_박지호'!G117) -> 활동 없음 | I16: =IF('S04_최유진'!G117="","미선택",'S04_최유진'!G117) -> 미수집 | J16: =IF('S05_정하늘'!G117="","미선택",'S05_정하늘'!G117) -> 값 있음 | K16: =IF('S06_한도윤'!G117="","미선택",'S06_한도윤'!G117) -> 활동 없음
A17: 실무·진로 | B17: 12 | C17: 아르바이트경험 | D17: 기존 | E17: =IF('11_작성예시'!G125="","미선택",'11_작성예시'!G125) -> 값 있음 | F17: =IF('S01_김민준'!G125="","미선택",'S01_김민준'!G125) -> 값 있음 | G17: =IF('S02_이서연'!G125="","미선택",'S02_이서연'!G125) -> 값 있음 | H17: =IF('S03_박지호'!G125="","미선택",'S03_박지호'!G125) -> 활동 없음 | I17: =IF('S04_최유진'!G125="","미선택",'S04_최유진'!G125) -> 미선택 | J17: =IF('S05_정하늘'!G125="","미선택",'S05_정하늘'!G125) -> 활동 없음 | K17: =IF('S06_한도윤'!G125="","미선택",'S06_한도윤'!G125) -> 활동 없음
A18: 실무·진로 | B18: 13 | C18: 진로설계·취업상담 | D18: 추가 제안 | E18: =IF('11_작성예시'!G133="","미선택",'11_작성예시'!G133) -> 값 있음 | F18: =IF('S01_김민준'!G133="","미선택",'S01_김민준'!G133) -> 값 있음 | G18: =IF('S02_이서연'!G133="","미선택",'S02_이서연'!G133) -> 값 있음 | H18: =IF('S03_박지호'!G133="","미선택",'S03_박지호'!G133) -> 값 있음 | I18: =IF('S04_최유진'!G133="","미선택",'S04_최유진'!G133) -> 미수집 | J18: =IF('S05_정하늘'!G133="","미선택",'S05_정하늘'!G133) -> 값 있음 | K18: =IF('S06_한도윤'!G133="","미선택",'S06_한도윤'!G133) -> 값 있음
A19: 창의·도전 | B19: 14 | C19: 공모전 참가·수상 | D19: 기존 + SKKU 확보가능 | E19: =IF('11_작성예시'!G141="","미선택",'11_작성예시'!G141) -> 값 있음 | F19: =IF('S01_김민준'!G141="","미선택",'S01_김민준'!G141) -> 값 있음 | G19: =IF('S02_이서연'!G141="","미선택",'S02_이서연'!G141) -> 값 있음 | H19: =IF('S03_박지호'!G141="","미선택",'S03_박지호'!G141) -> 활동 없음 | I19: =IF('S04_최유진'!G141="","미선택",'S04_최유진'!G141) -> 미수집 | J19: =IF('S05_정하늘'!G141="","미선택",'S05_정하늘'!G141) -> 값 있음 | K19: =IF('S06_한도윤'!G141="","미선택",'S06_한도윤'!G141) -> 활동 없음
A20: 창의·도전 | B20: 15 | C20: 창업활동 | D20: 기존 + SKKU 확보가능 | E20: =IF('11_작성예시'!G151="","미선택",'11_작성예시'!G151) -> 값 있음 | F20: =IF('S01_김민준'!G151="","미선택",'S01_김민준'!G151) -> 활동 없음 | G20: =IF('S02_이서연'!G151="","미선택",'S02_이서연'!G151) -> 활동 없음 | H20: =IF('S03_박지호'!G151="","미선택",'S03_박지호'!G151) -> 활동 없음 | I20: =IF('S04_최유진'!G151="","미선택",'S04_최유진'!G151) -> 미선택 | J20: =IF('S05_정하늘'!G151="","미선택",'S05_정하늘'!G151) -> 활동 없음 | K20: =IF('S06_한도윤'!G151="","미선택",'S06_한도윤'!G151) -> 활동 없음
A21: 창의·도전 | B21: 16 | C21: 특허출원·SW 등록 | D21: SKKU 확보가능 | E21: =IF('11_작성예시'!G158="","미선택",'11_작성예시'!G158) -> 값 있음 | F21: =IF('S01_김민준'!G158="","미선택",'S01_김민준'!G158) -> 활동 없음 | G21: =IF('S02_이서연'!G158="","미선택",'S02_이서연'!G158) -> 활동 없음 | H21: =IF('S03_박지호'!G158="","미선택",'S03_박지호'!G158) -> 활동 없음 | I21: =IF('S04_최유진'!G158="","미선택",'S04_최유진'!G158) -> 미선택 | J21: =IF('S05_정하늘'!G158="","미선택",'S05_정하늘'!G158) -> 활동 없음 | K21: =IF('S06_한도윤'!G158="","미선택",'S06_한도윤'!G158) -> 활동 없음
A22: 글로벌 | B22: 17 | C22: 교환학생·해외경험 | D22: 기존 + SKKU 확보가능 | E22: =IF('11_작성예시'!G166="","미선택",'11_작성예시'!G166) -> 값 있음 | F22: =IF('S01_김민준'!G166="","미선택",'S01_김민준'!G166) -> 활동 없음 | G22: =IF('S02_이서연'!G166="","미선택",'S02_이서연'!G166) -> 활동 없음 | H22: =IF('S03_박지호'!G166="","미선택",'S03_박지호'!G166) -> 활동 없음 | I22: =IF('S04_최유진'!G166="","미선택",'S04_최유진'!G166) -> 미선택 | J22: =IF('S05_정하늘'!G166="","미선택",'S05_정하늘'!G166) -> 미선택 | K22: =IF('S06_한도윤'!G166="","미선택",'S06_한도윤'!G166) -> 값 있음
A23: 글로벌 | B23: 18 | C23: 외국어 수업 이수 | D23: SKKU 확보가능 | E23: =IF('11_작성예시'!G174="","미선택",'11_작성예시'!G174) -> 값 있음 | F23: =IF('S01_김민준'!G174="","미선택",'S01_김민준'!G174) -> 값 있음 | G23: =IF('S02_이서연'!G174="","미선택",'S02_이서연'!G174) -> 값 있음 | H23: =IF('S03_박지호'!G174="","미선택",'S03_박지호'!G174) -> 값 있음 | I23: =IF('S04_최유진'!G174="","미선택",'S04_최유진'!G174) -> 미선택 | J23: =IF('S05_정하늘'!G174="","미선택",'S05_정하늘'!G174) -> 값 있음 | K23: =IF('S06_한도윤'!G174="","미선택",'S06_한도윤'!G174) -> 값 있음
A24: 디지털·AI | B24: 19 | C24: AI교육 이수내역 | D24: 기존 + SKKU 확보가능 | E24: =IF('11_작성예시'!G181="","미선택",'11_작성예시'!G181) -> 값 있음 | F24: =IF('S01_김민준'!G181="","미선택",'S01_김민준'!G181) -> 값 있음 | G24: =IF('S02_이서연'!G181="","미선택",'S02_이서연'!G181) -> 값 있음 | H24: =IF('S03_박지호'!G181="","미선택",'S03_박지호'!G181) -> 값 있음 | I24: =IF('S04_최유진'!G181="","미선택",'S04_최유진'!G181) -> 미수집 | J24: =IF('S05_정하늘'!G181="","미선택",'S05_정하늘'!G181) -> 값 있음 | K24: =IF('S06_한도윤'!G181="","미선택",'S06_한도윤'!G181) -> 미수집
A25: 디지털·AI | B25: 20 | C25: AI 프로젝트·대회 | D25: SKKU 확보가능 | E25: =IF('11_작성예시'!G190="","미선택",'11_작성예시'!G190) -> 값 있음 | F25: =IF('S01_김민준'!G190="","미선택",'S01_김민준'!G190) -> 값 있음 | G25: =IF('S02_이서연'!G190="","미선택",'S02_이서연'!G190) -> 활동 없음 | H25: =IF('S03_박지호'!G190="","미선택",'S03_박지호'!G190) -> 활동 없음 | I25: =IF('S04_최유진'!G190="","미선택",'S04_최유진'!G190) -> 미선택 | J25: =IF('S05_정하늘'!G190="","미선택",'S05_정하늘'!G190) -> 활동 없음 | K25: =IF('S06_한도윤'!G190="","미선택",'S06_한도윤'!G190) -> 활동 없음
A26: 디지털·AI | B26: 21 | C26: 협업툴 활용경험 | D26: 기존 | E26: =IF('11_작성예시'!G198="","미선택",'11_작성예시'!G198) -> 값 있음 | F26: =IF('S01_김민준'!G198="","미선택",'S01_김민준'!G198) -> 값 있음 | G26: =IF('S02_이서연'!G198="","미선택",'S02_이서연'!G198) -> 값 있음 | H26: =IF('S03_박지호'!G198="","미선택",'S03_박지호'!G198) -> 값 있음 | I26: =IF('S04_최유진'!G198="","미선택",'S04_최유진'!G198) -> 미선택 | J26: =IF('S05_정하늘'!G198="","미선택",'S05_정하늘'!G198) -> 값 있음 | K26: =IF('S06_한도윤'!G198="","미선택",'S06_한도윤'!G198) -> 값 있음
A27: 공동체·리더십 | B27: 22 | C27: 동아리·학생회 활동 | D27: 기존 + SKKU 확보가능 | E27: =IF('11_작성예시'!G208="","미선택",'11_작성예시'!G208) -> 값 있음 | F27: =IF('S01_김민준'!G208="","미선택",'S01_김민준'!G208) -> 값 있음 | G27: =IF('S02_이서연'!G208="","미선택",'S02_이서연'!G208) -> 값 있음 | H27: =IF('S03_박지호'!G208="","미선택",'S03_박지호'!G208) -> 값 있음 | I27: =IF('S04_최유진'!G208="","미선택",'S04_최유진'!G208) -> 미수집 | J27: =IF('S05_정하늘'!G208="","미선택",'S05_정하늘'!G208) -> 값 있음 | K27: =IF('S06_한도윤'!G208="","미선택",'S06_한도윤'!G208) -> 값 있음
A28: 공동체·리더십 | B28: 23 | C28: 봉사활동 | D28: 기존 + SKKU 확보가능 | E28: =IF('11_작성예시'!G217="","미선택",'11_작성예시'!G217) -> 값 있음 | F28: =IF('S01_김민준'!G217="","미선택",'S01_김민준'!G217) -> 값 있음 | G28: =IF('S02_이서연'!G217="","미선택",'S02_이서연'!G217) -> 값 있음 | H28: =IF('S03_박지호'!G217="","미선택",'S03_박지호'!G217) -> 값 있음 | I28: =IF('S04_최유진'!G217="","미선택",'S04_최유진'!G217) -> 미수집 | J28: =IF('S05_정하늘'!G217="","미선택",'S05_정하늘'!G217) -> 값 있음 | K28: =IF('S06_한도윤'!G217="","미선택",'S06_한도윤'!G217) -> 값 있음
A29: 공동체·리더십 | B29: 24 | C29: 멘토링·학습공동체 | D29: 추가 제안 | E29: =IF('11_작성예시'!G227="","미선택",'11_작성예시'!G227) -> 값 있음 | F29: =IF('S01_김민준'!G227="","미선택",'S01_김민준'!G227) -> 값 있음 | G29: =IF('S02_이서연'!G227="","미선택",'S02_이서연'!G227) -> 활동 없음 | H29: =IF('S03_박지호'!G227="","미선택",'S03_박지호'!G227) -> 활동 없음 | I29: =IF('S04_최유진'!G227="","미선택",'S04_최유진'!G227) -> 미선택 | J29: =IF('S05_정하늘'!G227="","미선택",'S05_정하늘'!G227) -> 활동 없음 | K29: =IF('S06_한도윤'!G227="","미선택",'S06_한도윤'!G227) -> 값 있음
A30: 공동체·리더십 | B30: 25 | C30: 팀프로젝트 동료평가 | D30: 추가 제안 | E30: =IF('11_작성예시'!G235="","미선택",'11_작성예시'!G235) -> 값 있음 | F30: =IF('S01_김민준'!G235="","미선택",'S01_김민준'!G235) -> 값 있음 | G30: =IF('S02_이서연'!G235="","미선택",'S02_이서연'!G235) -> 미수집 | H30: =IF('S03_박지호'!G235="","미선택",'S03_박지호'!G235) -> 활동 없음 | I30: =IF('S04_최유진'!G235="","미선택",'S04_최유진'!G235) -> 미선택 | J30: =IF('S05_정하늘'!G235="","미선택",'S05_정하늘'!G235) -> 미수집 | K30: =IF('S06_한도윤'!G235="","미선택",'S06_한도윤'!G235) -> 활동 없음
A31: 자격·인증 | B31: 26 | C31: 자격증(어학) | D31: 기존 + SKKU 확보가능 | E31: =IF('11_작성예시'!G245="","미선택",'11_작성예시'!G245) -> 값 있음 | F31: =IF('S01_김민준'!G245="","미선택",'S01_김민준'!G245) -> 값 있음 | G31: =IF('S02_이서연'!G245="","미선택",'S02_이서연'!G245) -> 값 있음 | H31: =IF('S03_박지호'!G245="","미선택",'S03_박지호'!G245) -> 미수집 | I31: =IF('S04_최유진'!G245="","미선택",'S04_최유진'!G245) -> 미수집 | J31: =IF('S05_정하늘'!G245="","미선택",'S05_정하늘'!G245) -> 값 있음 | K31: =IF('S06_한도윤'!G245="","미선택",'S06_한도윤'!G245) -> 값 있음
A32: 자격·인증 | B32: 27 | C32: 자격증(기타/전공) | D32: 기존 + SKKU 확보가능 | E32: =IF('11_작성예시'!G254="","미선택",'11_작성예시'!G254) -> 값 있음 | F32: =IF('S01_김민준'!G254="","미선택",'S01_김민준'!G254) -> 값 있음 | G32: =IF('S02_이서연'!G254="","미선택",'S02_이서연'!G254) -> 값 있음 | H32: =IF('S03_박지호'!G254="","미선택",'S03_박지호'!G254) -> 활동 없음 | I32: =IF('S04_최유진'!G254="","미선택",'S04_최유진'!G254) -> 미수집 | J32: =IF('S05_정하늘'!G254="","미선택",'S05_정하늘'!G254) -> 값 있음 | K32: =IF('S06_한도윤'!G254="","미선택",'S06_한도윤'!G254) -> 활동 없음
A33: 자격·인증 | B33: 28 | C33: 전문직·공직 시험 | D33: SKKU 확보가능 | E33: =IF('11_작성예시'!G264="","미선택",'11_작성예시'!G264) -> 값 있음 | F33: =IF('S01_김민준'!G264="","미선택",'S01_김민준'!G264) -> 활동 없음 | G33: =IF('S02_이서연'!G264="","미선택",'S02_이서연'!G264) -> 활동 없음 | H33: =IF('S03_박지호'!G264="","미선택",'S03_박지호'!G264) -> 활동 없음 | I33: =IF('S04_최유진'!G264="","미선택",'S04_최유진'!G264) -> 미선택 | J33: =IF('S05_정하늘'!G264="","미선택",'S05_정하늘'!G264) -> 활동 없음 | K33: =IF('S06_한도윤'!G264="","미선택",'S06_한도윤'!G264) -> 활동 없음
A34: 자격·인증 | B34: 29 | C34: 3품인증 취득현황 | D34: SKKU 확보가능 | E34: =IF('11_작성예시'!G271="","미선택",'11_작성예시'!G271) -> 값 있음 | F34: =IF('S01_김민준'!G271="","미선택",'S01_김민준'!G271) -> 값 있음 | G34: =IF('S02_이서연'!G271="","미선택",'S02_이서연'!G271) -> 값 있음 | H34: =IF('S03_박지호'!G271="","미선택",'S03_박지호'!G271) -> 값 있음 | I34: =IF('S04_최유진'!G271="","미선택",'S04_최유진'!G271) -> 값 있음 | J34: =IF('S05_정하늘'!G271="","미선택",'S05_정하늘'!G271) -> 값 있음 | K34: =IF('S06_한도윤'!G271="","미선택",'S06_한도윤'!G271) -> 값 있음
A35: 자격·인증 | B35: 30 | C35: 비교과 이수시간 | D35: SKKU 확보가능 | E35: =IF('11_작성예시'!G279="","미선택",'11_작성예시'!G279) -> 값 있음 | F35: =IF('S01_김민준'!G279="","미선택",'S01_김민준'!G279) -> 값 있음 | G35: =IF('S02_이서연'!G279="","미선택",'S02_이서연'!G279) -> 값 있음 | H35: =IF('S03_박지호'!G279="","미선택",'S03_박지호'!G279) -> 값 있음 | I35: =IF('S04_최유진'!G279="","미선택",'S04_최유진'!G279) -> 값 있음 | J35: =IF('S05_정하늘'!G279="","미선택",'S05_정하늘'!G279) -> 값 있음 | K35: =IF('S06_한도윤'!G279="","미선택",'S06_한도윤'!G279) -> 값 있음
A36: 진단·자기평가 | B36: 31 | C36: SSCA 학생성공역량진단 | D36: SKKU 확보가능 | E36: =IF('11_작성예시'!G286="","미선택",'11_작성예시'!G286) -> 값 있음 | F36: =IF('S01_김민준'!G286="","미선택",'S01_김민준'!G286) -> 값 있음 | G36: =IF('S02_이서연'!G286="","미선택",'S02_이서연'!G286) -> 미수집 | H36: =IF('S03_박지호'!G286="","미선택",'S03_박지호'!G286) -> 값 있음 | I36: =IF('S04_최유진'!G286="","미선택",'S04_최유진'!G286) -> 미선택 | J36: =IF('S05_정하늘'!G286="","미선택",'S05_정하늘'!G286) -> 값 있음 | K36: =IF('S06_한도윤'!G286="","미선택",'S06_한도윤'!G286) -> 미수집
A37: 진단·자기평가 | B37: 32 | C37: 학습경험진단 | D37: SKKU 확보가능 | E37: =IF('11_작성예시'!G298="","미선택",'11_작성예시'!G298) -> 값 있음 | F37: =IF('S01_김민준'!G298="","미선택",'S01_김민준'!G298) -> 값 있음 | G37: =IF('S02_이서연'!G298="","미선택",'S02_이서연'!G298) -> 미수집 | H37: =IF('S03_박지호'!G298="","미선택",'S03_박지호'!G298) -> 값 있음 | I37: =IF('S04_최유진'!G298="","미선택",'S04_최유진'!G298) -> 미선택 | J37: =IF('S05_정하늘'!G298="","미선택",'S05_정하늘'!G298) -> 미수집 | K37: =IF('S06_한도윤'!G298="","미선택",'S06_한도윤'!G298) -> 미수집
A38: 진단·자기평가 | B38: 33 | C38: 활동 성찰 기록(STAR) | D38: 추가 제안 | E38: =IF('11_작성예시'!G305="","미선택",'11_작성예시'!G305) -> 값 있음 | F38: =IF('S01_김민준'!G305="","미선택",'S01_김민준'!G305) -> 값 있음 | G38: =IF('S02_이서연'!G305="","미선택",'S02_이서연'!G305) -> 값 있음 | H38: =IF('S03_박지호'!G305="","미선택",'S03_박지호'!G305) -> 값 있음 | I38: =IF('S04_최유진'!G305="","미선택",'S04_최유진'!G305) -> 미선택 | J38: =IF('S05_정하늘'!G305="","미선택",'S05_정하늘'!G305) -> 값 있음 | K38: =IF('S06_한도윤'!G305="","미선택",'S06_한도윤'!G305) -> 값 있음
A39: 진단·자기평가 | B39: 34 | C39: 교수 관찰 코멘트 | D39: 추가 제안 | E39: =IF('11_작성예시'!G313="","미선택",'11_작성예시'!G313) -> 값 있음 | F39: =IF('S01_김민준'!G313="","미선택",'S01_김민준'!G313) -> 미수집 | G39: =IF('S02_이서연'!G313="","미선택",'S02_이서연'!G313) -> 미수집 | H39: =IF('S03_박지호'!G313="","미선택",'S03_박지호'!G313) -> 미수집 | I39: =IF('S04_최유진'!G313="","미선택",'S04_최유진'!G313) -> 미선택 | J39: =IF('S05_정하늘'!G313="","미선택",'S05_정하늘'!G313) -> 미선택 | K39: =IF('S06_한도윤'!G313="","미선택",'S06_한도윤'!G313) -> 미수집
A41: 값 있음 | E41: =COUNTIF(E$6:E$39,"값 있음") -> 34 | F41: =COUNTIF(F$6:F$39,"값 있음") -> 28 | G41: =COUNTIF(G$6:G$39,"값 있음") -> 17 | H41: =COUNTIF(H$6:H$39,"값 있음") -> 18 | I41: =COUNTIF(I$6:I$39,"값 있음") -> 5 | J41: =COUNTIF(J$6:J$39,"값 있음") -> 19 | K41: =COUNTIF(K$6:K$39,"값 있음") -> 17
A42: 활동 없음 | E42: =COUNTIF(E$6:E$39,"활동 없음") -> 0 | F42: =COUNTIF(F$6:F$39,"활동 없음") -> 5 | G42: =COUNTIF(G$6:G$39,"활동 없음") -> 9 | H42: =COUNTIF(H$6:H$39,"활동 없음") -> 14 | I42: =COUNTIF(I$6:I$39,"활동 없음") -> 0 | J42: =COUNTIF(J$6:J$39,"활동 없음") -> 9 | K42: =COUNTIF(K$6:K$39,"활동 없음") -> 12
...

Sheet 10_빈양식
A1: 학생 역량 데이터 수집 양식 (성균관대학교 · 34개 카테고리 · 학생 1명 = 시트 1장)
A2: 연녹색 칸만 입력합니다. 한 칸에 값 하나, 숫자는 단위 없이, 날짜는 YYYY-MM(-DD). 카테고리마다 '데이터 상태'를 반드시 고르고, 행이 모자라면 표 안에 행을 삽입하세요. H열 자동점검에 ⚠가 뜨면 상태와 값을 다시 확인합니다.
A3: 범례 | B3: 입력 칸 | C3: 기존 항목 | D3: SKKU 확보가능 | E3: 추가 제안 | F3: 데이터 상태: 값 있음 / 활동 없음(0점) / 미수집(계산 제외) / 해당 없음(불이익 없음) · 상태 미선택 = 미수집 간주
A5: ■ 학생 기본정보 (학년 보정·학적 구분·전공 특수성 판단에 사용)
B6: 항목 | C6: 입력값 | D6: 형식 | E6: 입력 안내
B7: 학번 | D7: 숫자 10자리(텍스트) | E7: 학사시스템 학번 그대로
B8: 이름 | D8: 텍스트
B9: 소속 대학 | D9: 텍스트 | E9: 예: 공과대학
B10: 주전공(학과) | D10: 텍스트 | E10: 예: 기계공학부
B11: 학년 | D11: 숫자 1~6 | E11: 학사시스템 기준 현재 학년(숫자만)
B12: 이수 완료 학기 수 | D12: 숫자 | E12: 휴학 학기 제외, 본교 기준. 학년 보정에 사용
B13: 학적 구분 | D13: 목록 | E13: 대학원생은 별도 기준 적용
B14: 입학 구분 | D14: 목록 | E14: 편입생은 본교 이수 학기만 반영
B15: 입학 연월 | D15: YYYY-MM | E15: 예: 2023-03
B16: 학적 상태 | D16: 목록
B17: 공학인증 대상 계열 | D17: 목록 | E17: N이면 4번 카테고리는 '해당 없음'
B18: 수집 기준일 | D18: YYYY-MM-DD | E18: 데이터 추출(또는 제출) 기준일
B19: 수집 경로 | D19: 목록
B20: 개인정보 수집·이용 동의 | D20: 목록 | E20: N이면 평가 대상에서 제외
A22: ■ 학업·교과
A23: 1 | B23: 성적데이터(전공·학기별) | F23: 데이터 상태 ▶ | H23: =IF(G23="",IF(COUNTA(C25:C27,B30:G37)>0,"⚠ 상태 미선택(입력값 있음)","상태 미선택 → 미수집 간주"),IF(G23="값 있음",IF(COUNTA(C25:C27,B30:G37)=0,"⚠ 값 있음인데 입력값 없음","✓ 정상"),IF(COUNTA(C25:C27,B30:G37)>0,"⚠ 상태와 입력값 불일치","✓ 정상"))) -> 상태 미선택 → 미수집 간주
B24: 출처: 학사시스템(성적) | 확보 구분: 기존 + SKKU 확보가능 | 관련 역량: 학업성취 / 직무전문성 | 비고: [C] 전공별·학기별 성적 통합. 학기별 추이로 '성장' 지표 추가 가능
B25: 전체 평점(누적) | D25: 숫자(소수 2자리) | E25: 예: 3.85
B26: 전공 평점(누적) | D26: 숫자(소수 2자리) | E26: 예: 3.92
B27: 평점 만점 기준 | D27: 숫자 | E27: 성균관대 4.5
A28: No | B28: 학기 | C28: 신청학점 | D28: 취득학점 | E28: 학기 평점 | F28: 학기 전공 평점 | G28: 비고
A29: 형식 | B29: YYYY-1 / YYYY-2 / YYYY-여름 / YYYY-겨울 | C29: 숫자 | D29: 숫자 | E29: 숫자 | F29: 숫자 | G29: 휴학·계절 등
A30: 1
A31: 2
A32: 3
A33: 4
A34: 5
A35: 6
A36: 7
A37: 8
A39: 2 | B39: 수업유형별 성적 | F39: 데이터 상태 ▶ | H39: =IF(G39="",IF(COUNTA(B43:G47)>0,"⚠ 상태 미선택(입력값 있음)","상태 미선택 → 미수집 간주"),IF(G39="값 있음",IF(COUNTA(B43:G47)=0,"⚠ 값 있음인데 입력값 없음","✓ 정상"),IF(COUNTA(B43:G47)>0,"⚠ 상태와 입력값 불일치","✓ 정상"))) -> 상태 미선택 → 미수집 간주
B40: 출처: 학사시스템(과목별 성적) + LMS(과제점수) | 확보 구분: 기존 | 관련 역량: 발표력 / 논리적사고 / 학업성취 | 비고: 과목에 '발표형·토론형' 태그가 있어야 자동 분류 가능
A41: No | B41: 과목명 | C41: 학기 | D41: 수업유형 | E41: 과목 성적 | F41: 과제·보고서 점수 | G41: 비고
A42: 형식 | B42: 텍스트 | C42: YYYY-1 / YYYY-2 / YYYY-여름 / YYYY-겨울 | D42: [발표형 / 토론형 / 과제·보고서형 / PBL형] | E42: [A+ / A0 / B+ / B0 / C+ / C0 / D+ / D0 / F / P] | F42: 숫자(100점) | G42: 텍스트
A43: 1
...

Sheet 11_작성예시
A1: [작성 예시] 김예시 — 34개 카테고리를 모두 채운 기준 예시 (가상 데이터)
A2: 평가 테스트 포인트: 34개 카테고리 전부 '값 있음' — 입력 형식의 기준 예시
A3: 범례 | B3: 입력 칸 | C3: 기존 항목 | D3: SKKU 확보가능 | E3: 추가 제안 | F3: 데이터 상태: 값 있음 / 활동 없음(0점) / 미수집(계산 제외) / 해당 없음(불이익 없음) · 상태 미선택 = 미수집 간주
A5: ■ 학생 기본정보 (학년 보정·학적 구분·전공 특수성 판단에 사용)
B6: 항목 | C6: 입력값 | D6: 형식 | E6: 입력 안내
B7: 학번 | C7: 2023313001 | D7: 숫자 10자리(텍스트) | E7: 학사시스템 학번 그대로
B8: 이름 | C8: 김예시 | D8: 텍스트
B9: 소속 대학 | C9: 공과대학 | D9: 텍스트 | E9: 예: 공과대학
B10: 주전공(학과) | C10: 시스템경영공학과 | D10: 텍스트 | E10: 예: 기계공학부
B11: 학년 | C11: 4 | D11: 숫자 1~6 | E11: 학사시스템 기준 현재 학년(숫자만)
B12: 이수 완료 학기 수 | C12: 7 | D12: 숫자 | E12: 휴학 학기 제외, 본교 기준. 학년 보정에 사용
B13: 학적 구분 | C13: 학부 | D13: 목록 | E13: 대학원생은 별도 기준 적용
B14: 입학 구분 | C14: 신입학 | D14: 목록 | E14: 편입생은 본교 이수 학기만 반영
B15: 입학 연월 | C15: 2023-03 | D15: YYYY-MM | E15: 예: 2023-03
B16: 학적 상태 | C16: 재학 | D16: 목록
B17: 공학인증 대상 계열 | C17: Y | D17: 목록 | E17: N이면 4번 카테고리는 '해당 없음'
B18: 수집 기준일 | C18: 2026-10-01 | D18: YYYY-MM-DD | E18: 데이터 추출(또는 제출) 기준일
B19: 수집 경로 | C19: 혼합 | D19: 목록
B20: 개인정보 수집·이용 동의 | C20: Y | D20: 목록 | E20: N이면 평가 대상에서 제외
A22: ■ 학업·교과
A23: 1 | B23: 성적데이터(전공·학기별) | F23: 데이터 상태 ▶ | G23: 값 있음 | H23: =IF(G23="",IF(COUNTA(C25:C27,B30:G37)>0,"⚠ 상태 미선택(입력값 있음)","상태 미선택 → 미수집 간주"),IF(G23="값 있음",IF(COUNTA(C25:C27,B30:G37)=0,"⚠ 값 있음인데 입력값 없음","✓ 정상"),IF(COUNTA(C25:C27,B30:G37)>0,"⚠ 상태와 입력값 불일치","✓ 정상"))) -> ✓ 정상
B24: 출처: 학사시스템(성적) | 확보 구분: 기존 + SKKU 확보가능 | 관련 역량: 학업성취 / 직무전문성 | 비고: [C] 전공별·학기별 성적 통합. 학기별 추이로 '성장' 지표 추가 가능
B25: 전체 평점(누적) | C25: 3.95 | D25: 숫자(소수 2자리) | E25: 예: 3.85
B26: 전공 평점(누적) | C26: 4.06 | D26: 숫자(소수 2자리) | E26: 예: 3.92
B27: 평점 만점 기준 | C27: 4.5 | D27: 숫자 | E27: 성균관대 4.5
A28: No | B28: 학기 | C28: 신청학점 | D28: 취득학점 | E28: 학기 평점 | F28: 학기 전공 평점 | G28: 비고
A29: 형식 | B29: YYYY-1 / YYYY-2 / YYYY-여름 / YYYY-겨울 | C29: 숫자 | D29: 숫자 | E29: 숫자 | F29: 숫자 | G29: 휴학·계절 등
A30: 1 | B30: 2023-1 | C30: 18 | D30: 18 | E30: 3.71 | F30: 3.8
A31: 2 | B31: 2023-2 | C31: 18 | D31: 18 | E31: 3.85 | F31: 3.9
A32: 3 | B32: 2024-1 | C32: 19 | D32: 19 | E32: 3.95 | F32: 4.1
A33: 4 | B33: 2024-2 | C33: 18 | D33: 18 | E33: 4.02 | F33: 4.15
A34: 5 | B34: 2025-1 | C34: 18 | D34: 18 | E34: 3.98 | F34: 4.05
A35: 6 | B35: 2025-2 | C35: 17 | D35: 17 | E35: 4.1 | F35: 4.2
A36: 7 | B36: 2026-1 | C36: 15 | D36: 15 | E36: 4.03 | F36: 4.12
A37: 8
A39: 2 | B39: 수업유형별 성적 | F39: 데이터 상태 ▶ | G39: 값 있음 | H39: =IF(G39="",IF(COUNTA(B43:G47)>0,"⚠ 상태 미선택(입력값 있음)","상태 미선택 → 미수집 간주"),IF(G39="값 있음",IF(COUNTA(B43:G47)=0,"⚠ 값 있음인데 입력값 없음","✓ 정상"),IF(COUNTA(B43:G47)>0,"⚠ 상태와 입력값 불일치","✓ 정상"))) -> ✓ 정상
B40: 출처: 학사시스템(과목별 성적) + LMS(과제점수) | 확보 구분: 기존 | 관련 역량: 발표력 / 논리적사고 / 학업성취 | 비고: 과목에 '발표형·토론형' 태그가 있어야 자동 분류 가능
A41: No | B41: 과목명 | C41: 학기 | D41: 수업유형 | E41: 과목 성적 | F41: 과제·보고서 점수 | G41: 비고
A42: 형식 | B42: 텍스트 | C42: YYYY-1 / YYYY-2 / YYYY-여름 / YYYY-겨울 | D42: [발표형 / 토론형 / 과제·보고서형 / PBL형] | E42: [A+ / A0 / B+ / B0 / C+ / C0 / D+ / D0 / F / P] | F42: 숫자(100점) | G42: 텍스트
A43: 1 | B43: 데이터분석과 의사결정 | C43: 2025-1 | D43: 발표형 | E43: A+ | F43: 95
...

Sheet S01_김민준
A1: [샘플 S01] 김민준 — 충실형 (가상 데이터)
A2: 평가 테스트 포인트: 대부분 값 있음 + 일부 '활동 없음'(창업·특허·해외) → 높은 충족도, 활동 없음은 0점 처리되는지 확인
A3: 범례 | B3: 입력 칸 | C3: 기존 항목 | D3: SKKU 확보가능 | E3: 추가 제안 | F3: 데이터 상태: 값 있음 / 활동 없음(0점) / 미수집(계산 제외) / 해당 없음(불이익 없음) · 상태 미선택 = 미수집 간주
A5: ■ 학생 기본정보 (학년 보정·학적 구분·전공 특수성 판단에 사용)
B6: 항목 | C6: 입력값 | D6: 형식 | E6: 입력 안내
B7: 학번 | C7: 2023310452 | D7: 숫자 10자리(텍스트) | E7: 학사시스템 학번 그대로
B8: 이름 | C8: 김민준 | D8: 텍스트
B9: 소속 대학 | C9: 공과대학 | D9: 텍스트 | E9: 예: 공과대학
B10: 주전공(학과) | C10: 기계공학부 | D10: 텍스트 | E10: 예: 기계공학부
B11: 학년 | C11: 4 | D11: 숫자 1~6 | E11: 학사시스템 기준 현재 학년(숫자만)
B12: 이수 완료 학기 수 | C12: 7 | D12: 숫자 | E12: 휴학 학기 제외, 본교 기준. 학년 보정에 사용
B13: 학적 구분 | C13: 학부 | D13: 목록 | E13: 대학원생은 별도 기준 적용
B14: 입학 구분 | C14: 신입학 | D14: 목록 | E14: 편입생은 본교 이수 학기만 반영
B15: 입학 연월 | C15: 2023-03 | D15: YYYY-MM | E15: 예: 2023-03
B16: 학적 상태 | C16: 재학 | D16: 목록
B17: 공학인증 대상 계열 | C17: Y | D17: 목록 | E17: N이면 4번 카테고리는 '해당 없음'
B18: 수집 기준일 | C18: 2026-10-01 | D18: YYYY-MM-DD | E18: 데이터 추출(또는 제출) 기준일
B19: 수집 경로 | C19: 시스템 연동 | D19: 목록
B20: 개인정보 수집·이용 동의 | C20: Y | D20: 목록 | E20: N이면 평가 대상에서 제외
A22: ■ 학업·교과
A23: 1 | B23: 성적데이터(전공·학기별) | F23: 데이터 상태 ▶ | G23: 값 있음 | H23: =IF(G23="",IF(COUNTA(C25:C27,B30:G37)>0,"⚠ 상태 미선택(입력값 있음)","상태 미선택 → 미수집 간주"),IF(G23="값 있음",IF(COUNTA(C25:C27,B30:G37)=0,"⚠ 값 있음인데 입력값 없음","✓ 정상"),IF(COUNTA(C25:C27,B30:G37)>0,"⚠ 상태와 입력값 불일치","✓ 정상"))) -> ✓ 정상
B24: 출처: 학사시스템(성적) | 확보 구분: 기존 + SKKU 확보가능 | 관련 역량: 학업성취 / 직무전문성 | 비고: [C] 전공별·학기별 성적 통합. 학기별 추이로 '성장' 지표 추가 가능
B25: 전체 평점(누적) | C25: 3.68 | D25: 숫자(소수 2자리) | E25: 예: 3.85
B26: 전공 평점(누적) | C26: 3.75 | D26: 숫자(소수 2자리) | E26: 예: 3.92
B27: 평점 만점 기준 | C27: 4.5 | D27: 숫자 | E27: 성균관대 4.5
A28: No | B28: 학기 | C28: 신청학점 | D28: 취득학점 | E28: 학기 평점 | F28: 학기 전공 평점 | G28: 비고
A29: 형식 | B29: YYYY-1 / YYYY-2 / YYYY-여름 / YYYY-겨울 | C29: 숫자 | D29: 숫자 | E29: 숫자 | F29: 숫자 | G29: 휴학·계절 등
A30: 1 | B30: 2023-1 | C30: 18 | D30: 18 | E30: 3.42 | F30: 3.5
A31: 2 | B31: 2023-2 | C31: 18 | D31: 18 | E31: 3.55 | F31: 3.6
A32: 3 | B32: 2024-1 | C32: 18 | D32: 18 | E32: 3.7 | F32: 3.72
A33: 4 | B33: 2024-2 | C33: 18 | D33: 18 | E33: 3.66 | F33: 3.8
A34: 5 | B34: 2025-1 | C34: 19 | D34: 19 | E34: 3.81 | F34: 3.85
A35: 6 | B35: 2025-2 | C35: 18 | D35: 18 | E35: 3.79 | F35: 3.88
A36: 7 | B36: 2026-1 | C36: 15 | D36: 15 | E36: 3.9 | F36: 3.95
A37: 8
A39: 2 | B39: 수업유형별 성적 | F39: 데이터 상태 ▶ | G39: 값 있음 | H39: =IF(G39="",IF(COUNTA(B43:G47)>0,"⚠ 상태 미선택(입력값 있음)","상태 미선택 → 미수집 간주"),IF(G39="값 있음",IF(COUNTA(B43:G47)=0,"⚠ 값 있음인데 입력값 없음","✓ 정상"),IF(COUNTA(B43:G47)>0,"⚠ 상태와 입력값 불일치","✓ 정상"))) -> ✓ 정상
B40: 출처: 학사시스템(과목별 성적) + LMS(과제점수) | 확보 구분: 기존 | 관련 역량: 발표력 / 논리적사고 / 학업성취 | 비고: 과목에 '발표형·토론형' 태그가 있어야 자동 분류 가능
A41: No | B41: 과목명 | C41: 학기 | D41: 수업유형 | E41: 과목 성적 | F41: 과제·보고서 점수 | G41: 비고
A42: 형식 | B42: 텍스트 | C42: YYYY-1 / YYYY-2 / YYYY-여름 / YYYY-겨울 | D42: [발표형 / 토론형 / 과제·보고서형 / PBL형] | E42: [A+ / A0 / B+ / B0 / C+ / C0 / D+ / D0 / F / P] | F42: 숫자(100점) | G42: 텍스트
A43: 1 | B43: 공학커뮤니케이션 | C43: 2024-1 | D43: 발표형 | E43: A+ | F43: 96
...

Sheet S02_이서연
A1: [샘플 S02] 이서연 — 일부 누락형 (가상 데이터)
A2: 평가 테스트 포인트: LMS·진단·동료평가 등 시스템 항목이 '미수집' + 공학인증 '해당 없음' → 미수집이 0점 처리되지 않는지, 해당 역량 충족도가 낮아지는지 확인
A3: 범례 | B3: 입력 칸 | C3: 기존 항목 | D3: SKKU 확보가능 | E3: 추가 제안 | F3: 데이터 상태: 값 있음 / 활동 없음(0점) / 미수집(계산 제외) / 해당 없음(불이익 없음) · 상태 미선택 = 미수집 간주
A5: ■ 학생 기본정보 (학년 보정·학적 구분·전공 특수성 판단에 사용)
B6: 항목 | C6: 입력값 | D6: 형식 | E6: 입력 안내
B7: 학번 | C7: 2024311187 | D7: 숫자 10자리(텍스트) | E7: 학사시스템 학번 그대로
B8: 이름 | C8: 이서연 | D8: 텍스트
B9: 소속 대학 | C9: 경영대학 | D9: 텍스트 | E9: 예: 공과대학
B10: 주전공(학과) | C10: 경영학과 | D10: 텍스트 | E10: 예: 기계공학부
B11: 학년 | C11: 3 | D11: 숫자 1~6 | E11: 학사시스템 기준 현재 학년(숫자만)
B12: 이수 완료 학기 수 | C12: 4 | D12: 숫자 | E12: 휴학 학기 제외, 본교 기준. 학년 보정에 사용
B13: 학적 구분 | C13: 학부 | D13: 목록 | E13: 대학원생은 별도 기준 적용
B14: 입학 구분 | C14: 신입학 | D14: 목록 | E14: 편입생은 본교 이수 학기만 반영
B15: 입학 연월 | C15: 2024-03 | D15: YYYY-MM | E15: 예: 2023-03
B16: 학적 상태 | C16: 재학 | D16: 목록
B17: 공학인증 대상 계열 | C17: N | D17: 목록 | E17: N이면 4번 카테고리는 '해당 없음'
B18: 수집 기준일 | C18: 2026-10-01 | D18: YYYY-MM-DD | E18: 데이터 추출(또는 제출) 기준일
B19: 수집 경로 | C19: 혼합 | D19: 목록
B20: 개인정보 수집·이용 동의 | C20: Y | D20: 목록 | E20: N이면 평가 대상에서 제외
A22: ■ 학업·교과
A23: 1 | B23: 성적데이터(전공·학기별) | F23: 데이터 상태 ▶ | G23: 값 있음 | H23: =IF(G23="",IF(COUNTA(C25:C27,B30:G37)>0,"⚠ 상태 미선택(입력값 있음)","상태 미선택 → 미수집 간주"),IF(G23="값 있음",IF(COUNTA(C25:C27,B30:G37)=0,"⚠ 값 있음인데 입력값 없음","✓ 정상"),IF(COUNTA(C25:C27,B30:G37)>0,"⚠ 상태와 입력값 불일치","✓ 정상"))) -> ✓ 정상
B24: 출처: 학사시스템(성적) | 확보 구분: 기존 + SKKU 확보가능 | 관련 역량: 학업성취 / 직무전문성 | 비고: [C] 전공별·학기별 성적 통합. 학기별 추이로 '성장' 지표 추가 가능
B25: 전체 평점(누적) | C25: 3.52 | D25: 숫자(소수 2자리) | E25: 예: 3.85
B26: 전공 평점(누적) | D26: 숫자(소수 2자리) | E26: 예: 3.92
B27: 평점 만점 기준 | C27: 4.5 | D27: 숫자 | E27: 성균관대 4.5
A28: No | B28: 학기 | C28: 신청학점 | D28: 취득학점 | E28: 학기 평점 | F28: 학기 전공 평점 | G28: 비고
A29: 형식 | B29: YYYY-1 / YYYY-2 / YYYY-여름 / YYYY-겨울 | C29: 숫자 | D29: 숫자 | E29: 숫자 | F29: 숫자 | G29: 휴학·계절 등
A30: 1 | B30: 2024-1 | C30: 18 | D30: 18 | E30: 3.3
A31: 2 | B31: 2024-2 | C31: 18 | D31: 18 | E31: 3.48
A32: 3 | B32: 2025-1 | C32: 18 | D32: 18 | E32: 3.61
A33: 4 | B33: 2025-2 | C33: 18 | D33: 18 | E33: 3.7
A34: 5
A35: 6
A36: 7
A37: 8
A39: 2 | B39: 수업유형별 성적 | F39: 데이터 상태 ▶ | G39: 값 있음 | H39: =IF(G39="",IF(COUNTA(B43:G47)>0,"⚠ 상태 미선택(입력값 있음)","상태 미선택 → 미수집 간주"),IF(G39="값 있음",IF(COUNTA(B43:G47)=0,"⚠ 값 있음인데 입력값 없음","✓ 정상"),IF(COUNTA(B43:G47)>0,"⚠ 상태와 입력값 불일치","✓ 정상"))) -> ✓ 정상
B40: 출처: 학사시스템(과목별 성적) + LMS(과제점수) | 확보 구분: 기존 | 관련 역량: 발표력 / 논리적사고 / 학업성취 | 비고: 과목에 '발표형·토론형' 태그가 있어야 자동 분류 가능
A41: No | B41: 과목명 | C41: 학기 | D41: 수업유형 | E41: 과목 성적 | F41: 과제·보고서 점수 | G41: 비고
A42: 형식 | B42: 텍스트 | C42: YYYY-1 / YYYY-2 / YYYY-여름 / YYYY-겨울 | D42: [발표형 / 토론형 / 과제·보고서형 / PBL형] | E42: [A+ / A0 / B+ / B0 / C+ / C0 / D+ / D0 / F / P] | F42: 숫자(100점) | G42: 텍스트
A43: 1 | B43: 마케팅원론 | C43: 2025-1 | D43: 발표형 | E43: A0 | F43: 91
...

Sheet S03_박지호
A1: [샘플 S03] 박지호 — 정보 적은 신입생형 (가상 데이터)
A2: 평가 테스트 포인트: 1학기만 이수, 대부분 '활동 없음' → 학년 보정(이수 1학기)이 적용되는지, 어학 '미수집'과 자격증 '활동 없음'이 다르게 처리되는지 확인
A3: 범례 | B3: 입력 칸 | C3: 기존 항목 | D3: SKKU 확보가능 | E3: 추가 제안 | F3: 데이터 상태: 값 있음 / 활동 없음(0점) / 미수집(계산 제외) / 해당 없음(불이익 없음) · 상태 미선택 = 미수집 간주
A5: ■ 학생 기본정보 (학년 보정·학적 구분·전공 특수성 판단에 사용)
B6: 항목 | C6: 입력값 | D6: 형식 | E6: 입력 안내
B7: 학번 | C7: 2026312045 | D7: 숫자 10자리(텍스트) | E7: 학사시스템 학번 그대로
B8: 이름 | C8: 박지호 | D8: 텍스트
B9: 소속 대학 | C9: 소프트웨어융합대학 | D9: 텍스트 | E9: 예: 공과대학
B10: 주전공(학과) | C10: 소프트웨어학과 | D10: 텍스트 | E10: 예: 기계공학부
B11: 학년 | C11: 1 | D11: 숫자 1~6 | E11: 학사시스템 기준 현재 학년(숫자만)
B12: 이수 완료 학기 수 | C12: 1 | D12: 숫자 | E12: 휴학 학기 제외, 본교 기준. 학년 보정에 사용
B13: 학적 구분 | C13: 학부 | D13: 목록 | E13: 대학원생은 별도 기준 적용
B14: 입학 구분 | C14: 신입학 | D14: 목록 | E14: 편입생은 본교 이수 학기만 반영
B15: 입학 연월 | C15: 2026-03 | D15: YYYY-MM | E15: 예: 2023-03
B16: 학적 상태 | C16: 재학 | D16: 목록
B17: 공학인증 대상 계열 | C17: Y | D17: 목록 | E17: N이면 4번 카테고리는 '해당 없음'
B18: 수집 기준일 | C18: 2026-10-01 | D18: YYYY-MM-DD | E18: 데이터 추출(또는 제출) 기준일
B19: 수집 경로 | C19: 시스템 연동 | D19: 목록
B20: 개인정보 수집·이용 동의 | C20: Y | D20: 목록 | E20: N이면 평가 대상에서 제외
A22: ■ 학업·교과
A23: 1 | B23: 성적데이터(전공·학기별) | F23: 데이터 상태 ▶ | G23: 값 있음 | H23: =IF(G23="",IF(COUNTA(C25:C27,B30:G37)>0,"⚠ 상태 미선택(입력값 있음)","상태 미선택 → 미수집 간주"),IF(G23="값 있음",IF(COUNTA(C25:C27,B30:G37)=0,"⚠ 값 있음인데 입력값 없음","✓ 정상"),IF(COUNTA(C25:C27,B30:G37)>0,"⚠ 상태와 입력값 불일치","✓ 정상"))) -> ✓ 정상
B24: 출처: 학사시스템(성적) | 확보 구분: 기존 + SKKU 확보가능 | 관련 역량: 학업성취 / 직무전문성 | 비고: [C] 전공별·학기별 성적 통합. 학기별 추이로 '성장' 지표 추가 가능
B25: 전체 평점(누적) | C25: 3.4 | D25: 숫자(소수 2자리) | E25: 예: 3.85
B26: 전공 평점(누적) | C26: 3.55 | D26: 숫자(소수 2자리) | E26: 예: 3.92
B27: 평점 만점 기준 | C27: 4.5 | D27: 숫자 | E27: 성균관대 4.5
A28: No | B28: 학기 | C28: 신청학점 | D28: 취득학점 | E28: 학기 평점 | F28: 학기 전공 평점 | G28: 비고
A29: 형식 | B29: YYYY-1 / YYYY-2 / YYYY-여름 / YYYY-겨울 | C29: 숫자 | D29: 숫자 | E29: 숫자 | F29: 숫자 | G29: 휴학·계절 등
A30: 1 | B30: 2026-1 | C30: 19 | D30: 19 | E30: 3.4 | F30: 3.55
A31: 2
A32: 3
A33: 4
A34: 5
A35: 6
A36: 7
A37: 8
A39: 2 | B39: 수업유형별 성적 | F39: 데이터 상태 ▶ | G39: 값 있음 | H39: =IF(G39="",IF(COUNTA(B43:G47)>0,"⚠ 상태 미선택(입력값 있음)","상태 미선택 → 미수집 간주"),IF(G39="값 있음",IF(COUNTA(B43:G47)=0,"⚠ 값 있음인데 입력값 없음","✓ 정상"),IF(COUNTA(B43:G47)>0,"⚠ 상태와 입력값 불일치","✓ 정상"))) -> ✓ 정상
B40: 출처: 학사시스템(과목별 성적) + LMS(과제점수) | 확보 구분: 기존 | 관련 역량: 발표력 / 논리적사고 / 학업성취 | 비고: 과목에 '발표형·토론형' 태그가 있어야 자동 분류 가능
A41: No | B41: 과목명 | C41: 학기 | D41: 수업유형 | E41: 과목 성적 | F41: 과제·보고서 점수 | G41: 비고
A42: 형식 | B42: 텍스트 | C42: YYYY-1 / YYYY-2 / YYYY-여름 / YYYY-겨울 | D42: [발표형 / 토론형 / 과제·보고서형 / PBL형] | E42: [A+ / A0 / B+ / B0 / C+ / C0 / D+ / D0 / F / P] | F42: 숫자(100점) | G42: 텍스트
A43: 1 | B43: 글쓰기와 발표 | C43: 2026-1 | D43: 발표형 | E43: B+ | F43: 86
...

Sheet S04_최유진
A1: [샘플 S04] 최유진 — 다수 누락형 (가상 데이터)
A2: 평가 테스트 포인트: 성적·수강·3품·비교과만 있고 나머지 대부분 미수집(일부는 상태조차 미선택) → 대부분 역량 '판정 보류'가 나와야 정상
A3: 범례 | B3: 입력 칸 | C3: 기존 항목 | D3: SKKU 확보가능 | E3: 추가 제안 | F3: 데이터 상태: 값 있음 / 활동 없음(0점) / 미수집(계산 제외) / 해당 없음(불이익 없음) · 상태 미선택 = 미수집 간주
A5: ■ 학생 기본정보 (학년 보정·학적 구분·전공 특수성 판단에 사용)
B6: 항목 | C6: 입력값 | D6: 형식 | E6: 입력 안내
B7: 학번 | C7: 2022315533 | D7: 숫자 10자리(텍스트) | E7: 학사시스템 학번 그대로
B8: 이름 | C8: 최유진 | D8: 텍스트
B9: 소속 대학 | C9: 사회과학대학 | D9: 텍스트 | E9: 예: 공과대학
B10: 주전공(학과) | C10: 사회학과 | D10: 텍스트 | E10: 예: 기계공학부
B11: 학년 | C11: 4 | D11: 숫자 1~6 | E11: 학사시스템 기준 현재 학년(숫자만)
B12: 이수 완료 학기 수 | C12: 7 | D12: 숫자 | E12: 휴학 학기 제외, 본교 기준. 학년 보정에 사용
B13: 학적 구분 | C13: 학부 | D13: 목록 | E13: 대학원생은 별도 기준 적용
B14: 입학 구분 | C14: 신입학 | D14: 목록 | E14: 편입생은 본교 이수 학기만 반영
B15: 입학 연월 | C15: 2022-03 | D15: YYYY-MM | E15: 예: 2023-03
B16: 학적 상태 | C16: 재학 | D16: 목록
B17: 공학인증 대상 계열 | C17: N | D17: 목록 | E17: N이면 4번 카테고리는 '해당 없음'
B18: 수집 기준일 | C18: 2026-10-01 | D18: YYYY-MM-DD | E18: 데이터 추출(또는 제출) 기준일
B19: 수집 경로 | C19: 시스템 연동 | D19: 목록
B20: 개인정보 수집·이용 동의 | C20: Y | D20: 목록 | E20: N이면 평가 대상에서 제외
A22: ■ 학업·교과
A23: 1 | B23: 성적데이터(전공·학기별) | F23: 데이터 상태 ▶ | G23: 값 있음 | H23: =IF(G23="",IF(COUNTA(C25:C27,B30:G37)>0,"⚠ 상태 미선택(입력값 있음)","상태 미선택 → 미수집 간주"),IF(G23="값 있음",IF(COUNTA(C25:C27,B30:G37)=0,"⚠ 값 있음인데 입력값 없음","✓ 정상"),IF(COUNTA(C25:C27,B30:G37)>0,"⚠ 상태와 입력값 불일치","✓ 정상"))) -> ✓ 정상
B24: 출처: 학사시스템(성적) | 확보 구분: 기존 + SKKU 확보가능 | 관련 역량: 학업성취 / 직무전문성 | 비고: [C] 전공별·학기별 성적 통합. 학기별 추이로 '성장' 지표 추가 가능
B25: 전체 평점(누적) | C25: 3.31 | D25: 숫자(소수 2자리) | E25: 예: 3.85
B26: 전공 평점(누적) | C26: 3.4 | D26: 숫자(소수 2자리) | E26: 예: 3.92
B27: 평점 만점 기준 | C27: 4.5 | D27: 숫자 | E27: 성균관대 4.5
A28: No | B28: 학기 | C28: 신청학점 | D28: 취득학점 | E28: 학기 평점 | F28: 학기 전공 평점 | G28: 비고
A29: 형식 | B29: YYYY-1 / YYYY-2 / YYYY-여름 / YYYY-겨울 | C29: 숫자 | D29: 숫자 | E29: 숫자 | F29: 숫자 | G29: 휴학·계절 등
A30: 1 | B30: 2022-1 | C30: 18 | D30: 18 | E30: 3.1 | F30: 3.2
A31: 2 | B31: 2022-2 | C31: 18 | D31: 18 | E31: 3.25 | F31: 3.3
A32: 3 | B32: 2023-1 | C32: 18 | D32: 17 | E32: 3.02 | F32: 3.1
A33: 4 | B33: 2023-2 | G33: 휴학
A34: 5 | B34: 2024-1 | G34: 휴학
A35: 6 | B35: 2024-2 | C35: 18 | D35: 18 | E35: 3.45 | F35: 3.5
A36: 7 | B36: 2025-1 | C36: 18 | D36: 18 | E36: 3.5 | F36: 3.55
A37: 8 | B37: 2025-2 | C37: 18 | D37: 18 | E37: 3.6 | F37: 3.62
A39: 2 | B39: 수업유형별 성적 | F39: 데이터 상태 ▶ | H39: =IF(G39="",IF(COUNTA(B43:G47)>0,"⚠ 상태 미선택(입력값 있음)","상태 미선택 → 미수집 간주"),IF(G39="값 있음",IF(COUNTA(B43:G47)=0,"⚠ 값 있음인데 입력값 없음","✓ 정상"),IF(COUNTA(B43:G47)>0,"⚠ 상태와 입력값 불일치","✓ 정상"))) -> 상태 미선택 → 미수집 간주
B40: 출처: 학사시스템(과목별 성적) + LMS(과제점수) | 확보 구분: 기존 | 관련 역량: 발표력 / 논리적사고 / 학업성취 | 비고: 과목에 '발표형·토론형' 태그가 있어야 자동 분류 가능
A41: No | B41: 과목명 | C41: 학기 | D41: 수업유형 | E41: 과목 성적 | F41: 과제·보고서 점수 | G41: 비고
A42: 형식 | B42: 텍스트 | C42: YYYY-1 / YYYY-2 / YYYY-여름 / YYYY-겨울 | D42: [발표형 / 토론형 / 과제·보고서형 / PBL형] | E42: [A+ / A0 / B+ / B0 / C+ / C0 / D+ / D0 / F / P] | F42: 숫자(100점) | G42: 텍스트
A43: 1
...

Sheet S05_정하늘
A1: [샘플 S05] 정하늘 — 비정형·오류 입력형 (가상 데이터)
A2: 평가 테스트 포인트: 자유서술·단위 포함·날짜형식 혼재·한 칸 여러 값·상태-값 불일치 → 파싱 규칙과 ⚠ 자동점검이 잡아내는지 확인
A3: 범례 | B3: 입력 칸 | C3: 기존 항목 | D3: SKKU 확보가능 | E3: 추가 제안 | F3: 데이터 상태: 값 있음 / 활동 없음(0점) / 미수집(계산 제외) / 해당 없음(불이익 없음) · 상태 미선택 = 미수집 간주
A5: ■ 학생 기본정보 (학년 보정·학적 구분·전공 특수성 판단에 사용)
B6: 항목 | C6: 입력값 | D6: 형식 | E6: 입력 안내
B7: 학번 | C7: 2025316290 | D7: 숫자 10자리(텍스트) | E7: 학사시스템 학번 그대로
B8: 이름 | C8: 정하늘 | D8: 텍스트
B9: 소속 대학 | C9: 경제대학 | D9: 텍스트 | E9: 예: 공과대학
B10: 주전공(학과) | C10: 글로벌경제 | D10: 텍스트 | E10: 예: 기계공학부
B11: 학년 | C11: 2학년 | D11: 숫자 1~6 | E11: 학사시스템 기준 현재 학년(숫자만)
B12: 이수 완료 학기 수 | C12: 2 | D12: 숫자 | E12: 휴학 학기 제외, 본교 기준. 학년 보정에 사용
B13: 학적 구분 | C13: 학부 | D13: 목록 | E13: 대학원생은 별도 기준 적용
B14: 입학 구분 | C14: 신입학 | D14: 목록 | E14: 편입생은 본교 이수 학기만 반영
B15: 입학 연월 | C15: 25.03 | D15: YYYY-MM | E15: 예: 2023-03
B16: 학적 상태 | C16: 재학 | D16: 목록
B17: 공학인증 대상 계열 | D17: 목록 | E17: N이면 4번 카테고리는 '해당 없음'
B18: 수집 기준일 | C18: 2026/10/1 | D18: YYYY-MM-DD | E18: 데이터 추출(또는 제출) 기준일
B19: 수집 경로 | C19: 학생 직접 입력 | D19: 목록
B20: 개인정보 수집·이용 동의 | C20: Y | D20: 목록 | E20: N이면 평가 대상에서 제외
A22: ■ 학업·교과
A23: 1 | B23: 성적데이터(전공·학기별) | F23: 데이터 상태 ▶ | G23: 값 있음 | H23: =IF(G23="",IF(COUNTA(C25:C27,B30:G37)>0,"⚠ 상태 미선택(입력값 있음)","상태 미선택 → 미수집 간주"),IF(G23="값 있음",IF(COUNTA(C25:C27,B30:G37)=0,"⚠ 값 있음인데 입력값 없음","✓ 정상"),IF(COUNTA(C25:C27,B30:G37)>0,"⚠ 상태와 입력값 불일치","✓ 정상"))) -> ✓ 정상
B24: 출처: 학사시스템(성적) | 확보 구분: 기존 + SKKU 확보가능 | 관련 역량: 학업성취 / 직무전문성 | 비고: [C] 전공별·학기별 성적 통합. 학기별 추이로 '성장' 지표 추가 가능
B25: 전체 평점(누적) | C25: 3.7/4.5 | D25: 숫자(소수 2자리) | E25: 예: 3.85
B26: 전공 평점(누적) | D26: 숫자(소수 2자리) | E26: 예: 3.92
B27: 평점 만점 기준 | C27: 4.5 | D27: 숫자 | E27: 성균관대 4.5
A28: No | B28: 학기 | C28: 신청학점 | D28: 취득학점 | E28: 학기 평점 | F28: 학기 전공 평점 | G28: 비고
A29: 형식 | B29: YYYY-1 / YYYY-2 / YYYY-여름 / YYYY-겨울 | C29: 숫자 | D29: 숫자 | E29: 숫자 | F29: 숫자 | G29: 휴학·계절 등
A30: 1 | B30: 25년 1학기 | C30: 19 | D30: 19 | E30: 3.62
A31: 2 | B31: 2025-2 | C31: 18학점 | D31: 18 | E31: 3.81 | F31: 3.9
A32: 3
A33: 4
A34: 5
A35: 6
A36: 7
A37: 8
A39: 2 | B39: 수업유형별 성적 | F39: 데이터 상태 ▶ | G39: 값 있음 | H39: =IF(G39="",IF(COUNTA(B43:G47)>0,"⚠ 상태 미선택(입력값 있음)","상태 미선택 → 미수집 간주"),IF(G39="값 있음",IF(COUNTA(B43:G47)=0,"⚠ 값 있음인데 입력값 없음","✓ 정상"),IF(COUNTA(B43:G47)>0,"⚠ 상태와 입력값 불일치","✓ 정상"))) -> ✓ 정상
B40: 출처: 학사시스템(과목별 성적) + LMS(과제점수) | 확보 구분: 기존 | 관련 역량: 발표력 / 논리적사고 / 학업성취 | 비고: 과목에 '발표형·토론형' 태그가 있어야 자동 분류 가능
A41: No | B41: 과목명 | C41: 학기 | D41: 수업유형 | E41: 과목 성적 | F41: 과제·보고서 점수 | G41: 비고
A42: 형식 | B42: 텍스트 | C42: YYYY-1 / YYYY-2 / YYYY-여름 / YYYY-겨울 | D42: [발표형 / 토론형 / 과제·보고서형 / PBL형] | E42: [A+ / A0 / B+ / B0 / C+ / C0 / D+ / D0 / F / P] | F42: 숫자(100점) | G42: 텍스트
A43: 1 | B43: 경제학원론 발표 | D43: 발표 | E43: A
...

Sheet S06_한도윤
A1: [샘플 S06] 한도윤 — 편입·편중형 + 기본정보 불일치 (가상 데이터)
A2: 평가 테스트 포인트: 편입 후 본교 1학기, 글로벌·어학 데이터만 풍부, 시트 학년(4)≠학사 명부(3) → '데이터 불일치 경고'와 편입생 공학인증 '해당 없음' 처리 확인
A3: 범례 | B3: 입력 칸 | C3: 기존 항목 | D3: SKKU 확보가능 | E3: 추가 제안 | F3: 데이터 상태: 값 있음 / 활동 없음(0점) / 미수집(계산 제외) / 해당 없음(불이익 없음) · 상태 미선택 = 미수집 간주
A5: ■ 학생 기본정보 (학년 보정·학적 구분·전공 특수성 판단에 사용)
B6: 항목 | C6: 입력값 | D6: 형식 | E6: 입력 안내
B7: 학번 | C7: 2026317702 | D7: 숫자 10자리(텍스트) | E7: 학사시스템 학번 그대로
B8: 이름 | C8: 한도윤 | D8: 텍스트
B9: 소속 대학 | C9: 공과대학 | D9: 텍스트 | E9: 예: 공과대학
B10: 주전공(학과) | C10: 화학공학부 | D10: 텍스트 | E10: 예: 기계공학부
B11: 학년 | C11: 4 | D11: 숫자 1~6 | E11: 학사시스템 기준 현재 학년(숫자만)
B12: 이수 완료 학기 수 | C12: 1 | D12: 숫자 | E12: 휴학 학기 제외, 본교 기준. 학년 보정에 사용
B13: 학적 구분 | C13: 학부 | D13: 목록 | E13: 대학원생은 별도 기준 적용
B14: 입학 구분 | C14: 편입학 | D14: 목록 | E14: 편입생은 본교 이수 학기만 반영
B15: 입학 연월 | C15: 2026-03 | D15: YYYY-MM | E15: 예: 2023-03
B16: 학적 상태 | C16: 재학 | D16: 목록
B17: 공학인증 대상 계열 | C17: Y | D17: 목록 | E17: N이면 4번 카테고리는 '해당 없음'
B18: 수집 기준일 | C18: 2026-10-01 | D18: YYYY-MM-DD | E18: 데이터 추출(또는 제출) 기준일
B19: 수집 경로 | C19: 혼합 | D19: 목록
B20: 개인정보 수집·이용 동의 | C20: Y | D20: 목록 | E20: N이면 평가 대상에서 제외
A22: ■ 학업·교과
A23: 1 | B23: 성적데이터(전공·학기별) | F23: 데이터 상태 ▶ | G23: 값 있음 | H23: =IF(G23="",IF(COUNTA(C25:C27,B30:G37)>0,"⚠ 상태 미선택(입력값 있음)","상태 미선택 → 미수집 간주"),IF(G23="값 있음",IF(COUNTA(C25:C27,B30:G37)=0,"⚠ 값 있음인데 입력값 없음","✓ 정상"),IF(COUNTA(C25:C27,B30:G37)>0,"⚠ 상태와 입력값 불일치","✓ 정상"))) -> ✓ 정상
B24: 출처: 학사시스템(성적) | 확보 구분: 기존 + SKKU 확보가능 | 관련 역량: 학업성취 / 직무전문성 | 비고: [C] 전공별·학기별 성적 통합. 학기별 추이로 '성장' 지표 추가 가능
B25: 전체 평점(누적) | C25: 4.21 | D25: 숫자(소수 2자리) | E25: 예: 3.85
B26: 전공 평점(누적) | C26: 4.3 | D26: 숫자(소수 2자리) | E26: 예: 3.92
B27: 평점 만점 기준 | C27: 4.5 | D27: 숫자 | E27: 성균관대 4.5
A28: No | B28: 학기 | C28: 신청학점 | D28: 취득학점 | E28: 학기 평점 | F28: 학기 전공 평점 | G28: 비고
A29: 형식 | B29: YYYY-1 / YYYY-2 / YYYY-여름 / YYYY-겨울 | C29: 숫자 | D29: 숫자 | E29: 숫자 | F29: 숫자 | G29: 휴학·계절 등
A30: 1 | B30: 2026-1 | C30: 18 | D30: 18 | E30: 4.21 | F30: 4.3 | G30: 편입 후 첫 학기(전적대 성적 미포함)
A31: 2
A32: 3
A33: 4
A34: 5
A35: 6
A36: 7
A37: 8
A39: 2 | B39: 수업유형별 성적 | F39: 데이터 상태 ▶ | G39: 값 있음 | H39: =IF(G39="",IF(COUNTA(B43:G47)>0,"⚠ 상태 미선택(입력값 있음)","상태 미선택 → 미수집 간주"),IF(G39="값 있음",IF(COUNTA(B43:G47)=0,"⚠ 값 있음인데 입력값 없음","✓ 정상"),IF(COUNTA(B43:G47)>0,"⚠ 상태와 입력값 불일치","✓ 정상"))) -> ✓ 정상
B40: 출처: 학사시스템(과목별 성적) + LMS(과제점수) | 확보 구분: 기존 | 관련 역량: 발표력 / 논리적사고 / 학업성취 | 비고: 과목에 '발표형·토론형' 태그가 있어야 자동 분류 가능
A41: No | B41: 과목명 | C41: 학기 | D41: 수업유형 | E41: 과목 성적 | F41: 과제·보고서 점수 | G41: 비고
A42: 형식 | B42: 텍스트 | C42: YYYY-1 / YYYY-2 / YYYY-여름 / YYYY-겨울 | D42: [발표형 / 토론형 / 과제·보고서형 / PBL형] | E42: [A+ / A0 / B+ / B0 / C+ / C0 / D+ / D0 / F / P] | F42: 숫자(100점) | G42: 텍스트
A43: 1 | B43: 화공열역학 | C43: 2026-1 | D43: 과제·보고서형 | E43: A+ | F43: 95
...

Sheet 코드표
A1: 코드표 — 데이터 상태 정의와 드롭다운 허용값
A3: 데이터 상태 | B3: 언제 쓰나 | C3: 입력 칸 처리 | D3: 평가 시 처리(프롬프트 R2) | E3: 예시
A4: 값 있음 | B4: 실제 값이 하나라도 있을 때 | C4: 값을 입력 | D4: 계산에 사용 | E4: TOEIC 905
A5: 활동 없음 | B5: 확인 결과 해당 활동이 없을 때 | C5: 비워 둠 | D5: 0점으로 계산에 포함 | E5: 봉사 이력 조회 결과 0건
A6: 미수집 | B6: 시스템 미연동·학생 미제출 등으로 확인 못 했을 때 | C6: 비워 둠 | D6: 계산·분모에서 제외, 데이터 충족도 하락 (0점 처리 금지) | E6: SSCA 미응시, LMS 미연동
A7: 해당 없음 | B7: 제도상 대상이 아닐 때 | C7: 비워 둠 | D7: 제외, 불이익 없음 | E7: 비공학 전공의 공학인증, 편입생 인증 비대상
A8: (미선택) | B8: 상태를 고르지 않음 | C8: - | D8: 미수집으로 간주 + 자동점검 표시 | E8: -
A10: ※ 항목 단위 규칙: 상태가 '값 있음'인 카테고리 안에서 일부 칸만 빈 경우, 그 칸만 미수집으로 봅니다. 수치 0은 '측정된 0'(값 있음)입니다.
A12: No | B12: 카테고리 | C12: 항목 | D12: 허용값(드롭다운)
A13: 기본 | B13: 학생 기본정보 | C13: 학적 구분 | D13: 학부 / 석사 / 박사 / 석박통합
A14: 기본 | B14: 학생 기본정보 | C14: 입학 구분 | D14: 신입학 / 편입학 / 재입학
A15: 기본 | B15: 학생 기본정보 | C15: 학적 상태 | D15: 재학 / 휴학 / 수료
A16: 기본 | B16: 학생 기본정보 | C16: 공학인증 대상 계열 | D16: Y / N
A17: 기본 | B17: 학생 기본정보 | C17: 수집 경로 | D17: 시스템 연동 / 학생 직접 입력 / 혼합
A18: 기본 | B18: 학생 기본정보 | C18: 개인정보 수집·이용 동의 | D18: Y / N
A19: 2 | B19: 수업유형별 성적 | C19: 수업유형 | D19: 발표형 / 토론형 / 과제·보고서형 / PBL형
A20: 2 | B20: 수업유형별 성적 | C20: 과목 성적 | D20: A+ / A0 / B+ / B0 / C+ / C0 / D+ / D0 / F / P
A21: 3 | B21: 수강과목·심화·융합 이수 | C21: 전공 구분 | D21: 주전공 / 복수전공 / 부전공 / 연계전공 / 융합전공 / 심화전공
A22: 3 | B22: 수강과목·심화·융합 이수 | C22: 이수 상태 | D22: 신청 / 이수중 / 이수완료
A23: 4 | B23: 공학인증 | C23: 공학인증 대상 여부 | D23: 대상 / 비대상
A24: 4 | B24: 공학인증 | C24: 이수 상태 | D24: 이수중 / 이수완료 / 미이수 / 포기
A25: 8 | B25: 학회·연구활동 | C25: 활동 유형 | D25: 학부연구생 / URP / 학회 / 연구실 인턴 / 팀연구프로젝트
A26: 9 | B26: 정보탐색 결과물(논문·보고서) | C26: 유형 | D26: 논문 / 보고서 / 학술발표자료
A27: 9 | B27: 정보탐색 결과물(논문·보고서) | C27: 게재 수준 | D27: 국제학술지 / 국내학술지 / 국제학술대회 / 국내학술대회 / 교내
A28: 9 | B28: 정보탐색 결과물(논문·보고서) | C28: 진행 상태 | D28: 게재 / 게재승인 / 투고 / 작성중
A29: 9 | B29: 정보탐색 결과물(논문·보고서) | C29: 저자 구분 | D29: 단독 / 제1저자 / 공동저자
A30: 11 | B30: 인턴·현장실습 | C30: 유형 | D30: 인턴십 / 현장실습 / 연구체험 / 문제해결프로젝트
... A60: 34 | B60: 교수 관찰 코멘트 | C60: 관계 | D60: 지도교수 / 수업 담당교수

Sheet 데이터카테고리_마스터
A1: 측정지표 데이터 카테고리 마스터 (성균관대학교 기준 · 기존 + SKKU 확보가능 + 추가 제안)
A2: 범례: 흰색 = 기존 데이터셋 항목(성균관대 항목과 통합된 경우 포함) | 하늘색 = 성균관대 시스템에서 새로 확보 가능 | 연노랑 = 평가 품질을 위해 추가 제안
A4: No | B4: 대분류 | C4: 카테고리 | D4: 설명(포함되는 세부 측정지표) | E4: 데이터 형태 | F4: 수집 출처(시스템) | G4: 확보 구분 | H4: 관련 역량(마인드맵 기준) | I4: 비고
A5: 1 | B5: 학업·교과 | C5: 성적데이터(전공·학기별) | D5: 전공 평균성적, 학기별 성적 추이, 전체 평점 | E5: 수치 | F5: 학사시스템(성적) | G5: 기존 + SKKU 확보가능 | H5: 학업성취 / 직무전문성 | I5: [C] 전공별·학기별 성적 통합. 학기별 추이로 '성장' 지표 추가 가능 | J5: 학업·교과
A6: 2 | C6: 수업유형별 성적 | D6: 발표·토론 수업성적, 과제·보고서 평가점수 | E6: 수치·범주 | F6: 학사시스템(과목별 성적) + LMS(과제점수) | G6: 기존 | H6: 발표력 / 논리적사고 / 학업성취 | I6: 과목에 '발표형·토론형' 태그가 있어야 자동 분류 가능 | J6: 학업·교과
A7: 3 | C7: 수강과목·심화·융합 이수 | D7: 수강과목 내역, 심화전공·심화과목 이수, 복수·연계·융합전공 | E7: 범주 | F7: 학사시스템(수강내역) | G7: 기존 + SKKU 확보가능 | H7: 탐구력 / 종합적사고력(융합적 사고) / 직무전문성 | I7: 마인드맵의 '융합 전공'은 기존 데이터셋에 없음 → 수강내역에서 도출 | J7: 학업·교과
A8: 4 | C8: 공학인증 | D8: 공학교육인증 프로그램 이수 여부 | E8: 범주 | F8: 학사시스템 | G8: SKKU 확보가능 | H8: 직무전문성 | I8: 공학계열 한정 → 비대상 전공은 '해당 없음' 처리(불이익 방지) | J8: 학업·교과
A9: 5 | B9: 학습행동(LMS) | C9: LMS 학습데이터 | D9: 출석률, 과제기한준수율, 로그인주기, 퀴즈풀이횟수, 학습계획달성률 | E9: 수치 | F9: LMS(i-Campus) · 출석앱 | G9: 기존 | H9: 자기관리 / 성실성 | I9: 마인드맵 '퀴즈 생성 주기' vs 데이터 '퀴즈풀이횟수' 용어 통일 필요 | J9: 학습행동(LMS)
A10: 6 | C10: 교수면담·학업상담 | D10: 교수 면담 횟수, 학업상담 이력 | E10: 수치 | F10: 상담 기록 시스템 · LMS | G10: 기존 | H10: 성실성(수업참여도) / 소통능력 | I10: 기존 데이터셋에선 LMS 항목 안에 섞여 있어 분리 | J10: 학습행동(LMS)
A11: 7 | C11: 토론·게시판 참여 | D11: LMS 토론방 게시글·댓글 수, 질의응답 참여 | E11: 수치 | F11: LMS(i-Campus) | G11: 추가 제안 | H11: 소통능력 / 수업참여도 | I11: 교수 관심 '소통능력'의 정량 근거 보강 | J11: 학습행동(LMS)
A12: 8 | B12: 연구·학술 | C12: 학회·연구활동 | D12: 학부연구생/URP, 학회 활동, 연구실 인턴, 팀연구프로젝트 | E12: 범주·기간 | F12: 비교과·연구지원 시스템 | G12: 기존 + SKKU 확보가능 | H12: 탐구력 / 문제해결력 | I12: [B] 학회·연구 + [C] URP·팀연구프로젝트 통합 | J12: 연구·학술
A13: 9 | C13: 정보탐색 결과물(논문·보고서) | D13: 논문(게재·투고·작성 중), 보고서, 학술 발표자료 | E13: 범주·텍스트 | F13: 학생 등록(포트폴리오) | G13: 기존 | H13: 자원·정보기술활용(정보탐색) / 논리적사고 | I13: 게재 수준(학술지·학회·교내) 구분 기준 필요 | J13: 연구·학술
A14: 10 | C14: TA 활동 | D14: 교과목 조교(TA) 수행 이력, 기간 | E14: 범주·기간 | F14: 학사시스템 · 교수학습센터 | G14: SKKU 확보가능 | H14: 직무전문성 / 커뮤니케이션 / 책임감 | I14: 기존 데이터셋에 없는 신규 근거 | J14: 연구·학술
A15: 11 | B15: 실무·진로 | C15: 인턴·현장실습 | D15: 인턴십, 현장실습, 연구체험, 문제해결프로젝트 | E15: 범주·기간 | F15: 현장실습 지원 시스템 · 3품(인턴십) | G15: 기존 + SKKU 확보가능 | H15: 직무전문성 / 커뮤니케이션(협업) | I15: 기간(개월)과 직무 관련성을 함께 추출 | J15: 실무·진로
A16: 12 | C16: 아르바이트경험 | D16: 아르바이트 근무 이력, 기간 | E16: 텍스트·기간 | F16: 학생 등록(고용보험 자격이력 등) | G16: 기존 | H16: 커뮤니케이션 / 책임감 | I16: 증빙 신뢰도 낮음 → 기간 위주 정량화 권장 | J16: 실무·진로
A17: 13 | C17: 진로설계·취업상담 | D17: 진로·취업 상담 이력, 진로 목표 설정 기록 | E17: 텍스트·수치 | F17: 경력개발 · 상담 시스템 | G17: 추가 제안 | H17: 자기관리(계획 수립) / 직무전문성 | I17: '계획 수립 및 실행 능력'의 근거가 LMS 하나뿐인 공백 보완 | J17: 실무·진로
A18: 14 | B18: 창의·도전 | C18: 공모전 참가·수상 | D18: 각종 공모전·경진대회 참가 및 수상(등급·주관 수준) | E18: 범주 | F18: 비교과 시스템 · 3품(창의) | G18: 기존 + SKKU 확보가능 | H18: 창의 / 종합적사고력 / 문제해결력 / 도전정신 | I18: 수상 등급 × 주관 수준(교내·전국·국제) 매핑 필요 | J18: 창의·도전
A19: 15 | C19: 창업활동 | D19: 창업 교과목 이수, 창업 경진대회, 사업자등록 | E19: 범주 | F19: 학사시스템 · 창업지원 · 3품(창의) | G19: 기존 + SKKU 확보가능 | H19: 창의 / 도전정신 | J19: 창의·도전
A20: 16 | C20: 특허출원·SW 등록 | D20: 특허·실용신안·디자인 출원, SW 프로그램 등록 | E20: 범주 | F20: 3품(창의) 인증 · 학생 등록 | G20: SKKU 확보가능 | H20: 창의 / 도전정신 / 직무전문성 | I20: 기존 데이터셋에 없는 신규 근거 | J20: 창의·도전
A21: 17 | B21: 글로벌 | C21: 교환학생·해외경험 | D21: 교환학생, 어학연수, 해외봉사, 국제연구, 국제문화체험, 해외학습 | E21: 범주·기간 | F21: 국제처 · 3품(글로벌) | G21: 기존 + SKKU 확보가능 | H21: 글로벌(문화적 수용능력) | I21: [C] 국제연구·국제문화체험 항목 추가 | J21: 글로벌
A22: 18 | C22: 외국어 수업 이수 | D22: 국제어(외국어) 강의 이수 과목·학점 | E22: 수치 | F22: 학사시스템(수강내역) | G22: SKKU 확보가능 | H22: 글로벌(외국어 능력) | I22: 마인드맵(기업 관심-글로벌)에 있으나 기존 데이터셋에 없음 | J22: 글로벌
A23: 19 | B23: 디지털·AI | C23: AI교육 이수내역 | D23: AI 교과·비교과 교육, 생성형 AI·바이브 코딩 교육 | E23: 범주·시간 | F23: 학사시스템 · 비교과 · 3품(AI) | G23: 기존 + SKKU 확보가능 | H23: 자원·정보기술활용 / 디지털리터러시 | I23: 이수 '시간'까지 받으면 정량화 쉬워짐 | J23: 디지털·AI
A24: 20 | C24: AI 프로젝트·대회 | D24: AI 캡스톤 프로젝트, AI 대회·공모전 | E24: 범주 | F24: 학사시스템 · 3품(AI) | G24: SKKU 확보가능 | H24: 디지털리터러시(AI 활용) / 문제해결력 | I24: 공모전 항목과 중복 가산되지 않게 분리 | J24: 디지털·AI
A25: 21 | C25: 협업툴 활용경험 | D25: 노션·슬랙·깃허브·피그마 등 활용 경험 | E25: 텍스트 | F25: 학생 등록 | G25: 기존 | H25: 자원·정보기술활용 / 디지털리터러시 | I25: 자기 서술 위주 → 정성 판단 + 낮은 가중치 권장 | J25: 디지털·AI
A26: 22 | B26: 공동체·리더십 | C26: 동아리·학생회 활동 | D26: 동아리·학생회·학회 활동, 직책, 활동 기간 | E26: 범주·기간 | F26: 비교과 시스템 · 학생 등록 | G26: 기존 + SKKU 확보가능 | H26: 대인관계 / 리더십 / 커뮤니케이션 | I26: 직책(회장·부장·총무·부원) × 기간으로 정량화 | J26: 공동체·리더십
A27: 23 | C27: 봉사활동 | D27: 교내외 봉사(국내·국외), 유학생 봉사, 봉사 시간 | E27: 수치·범주 | F27: 1365 · 3품(인성) | G27: 기존 + SKKU 확보가능 | H27: 대인관계 / 리더십 / 문화적수용능력 | I27: 학년 보정(학기당 시간) 필요 | J27: 공동체·리더십
A28: 24 | C28: 멘토링·학습공동체 | D28: 튜터링·멘토링, 스터디·학습공동체 참여 | E28: 범주·기간 | F28: 교수학습센터 | G28: 추가 제안 | H28: 소통능력 / 대인관계 | I28: 교수 관심 '소통능력'의 '스터디 참여' 근거 확보 | J28: 공동체·리더십
A29: 25 | C29: 팀프로젝트 동료평가 | D29: 팀 과제 동료평가 점수·코멘트 | E29: 수치·텍스트 | F29: LMS(i-Campus) | G29: 추가 제안 | H29: 커뮤니케이션(협업) / 대인관계 / 리더십 | I29: 대인관계 역량을 '활동 여부'가 아닌 '평판'으로 측정할 수 있는 유일한 근거 | J29: 공동체·리더십
A30: 26 | B30: 자격·인증 | C30: 자격증(어학) | D30: TOEIC, TOEFL, TOEIC Speaking, OPIc, HSK, JPT, DELF 등 | E30: 수치·범주 | F30: 학생 등록(성적표) · 3품(글로벌) | G30: 기존 + SKKU 확보가능 | H30: 글로벌(언어 사용능력) | I30: 시험별 공통 척도 환산표 필요 | J30: 자격·인증
A31: 27 | C31: 자격증(기타/전공) | D31: 컴퓨터활용능력, MOS, ADSP, SQLD, 기사 등 | E31: 범주 | F31: 학생 등록 · 3품(창의-IT 활용) | G31: 기존 + SKKU 확보가능 | H31: 자원·정보기술활용 / 직무전문성 / 디지털리터러시 | I31: 자격증별 '등급·난이도' 매핑표 필요 | J31: 자격·인증
A32: 28 | C32: 전문직·공직 시험 | D32: 공개경쟁시험·5급 공채 등, 회계사·세무사·관세사 등 | E32: 범주 | F32: 3품(창의-진로개발) 인증 | G32: SKKU 확보가능 | H32: 직무전문성 / 도전정신 | I32: 단계(1차·최종) 구분 | J32: 자격·인증
A33: 29 | C33: 3품인증 취득현황 | D33: 인성품·글로벌품·창의품(AI·인턴십 영역 포함) 취득 여부 | E33: 범주 | F33: 3품인증 시스템 | G33: SKKU 확보가능 | H33: (복수 역량 종합) | I33: 하위 활동과 중복 가산 위험 → 가산점이 아닌 '참고 지표'로 권장 | J33: 자격·인증
A34: 30 | C34: 비교과 이수시간 | D34: 비교과 프로그램 누적 이수시간 (90시간 기준 등) | E34: 수치 | F34: 비교과 시스템 | G34: SKKU 확보가능 | H34: 자기관리 / 종합적사고력(융합적 사고) | I34: 학년 보정 필요 | J34: 자격·인증
A35: 31 | B35: 진단·자기평가 | C35: SSCA 학생성공역량진단 | D35: SSCA 검사 결과(역량별 자기진단 점수) | E35: 수치 | F35: 학생성공 게이트웨이 | G35: SKKU 확보가능 | H35: 전 역량(자기인식) | I35: 객관 점수에 합산하지 말고 '자기평가 vs 데이터 평가' 비교용으로 별도 표시 | J35: 진단·자기평가
A36: 32 | C36: 학습경험진단 | D36: 학습경험 설문 결과 | E36: 수치 | F36: 학생성공 게이트웨이 | G36: SKKU 확보가능 | H36: 자기관리 / 학업성취 | I36: SSCA와 동일하게 비교용 권장 | J36: 진단·자기평가
A37: 33 | C37: 활동 성찰 기록(STAR) | D37: 주요 활동별 상황·역할·행동·결과 서술 | E37: 텍스트 | F37: 학생 입력(포트폴리오) | G37: 추가 제안 | H37: 리더십 / 문제해결력 / 커뮤니케이션 등 정성 역량 | I37: 정성 루브릭이 판단할 '질적 근거'가 현재 거의 없음 → 가장 우선 확보 권장 | J37: 진단·자기평가
A38: 34 | C38: 교수 관찰 코멘트 | D38: 지도교수·수업 교수의 관찰 의견(선택) | E38: 텍스트 | F38: 교수 입력 | G38: 추가 제안 | H38: 교수 관심 역량 전반 | I38: 입력 부담 고려해 선택 항목으로 | J38: 진단·자기평가
A40: ※ 출처 시스템명(i-Campus, 학생성공 게이트웨이 등)은 공개 정보 기준이며, 실제 연동 가능 여부는 학교 담당 부서 확인이 필요합니다.

Sheet 대분류_요약
A1: 대분류별 항목 수
A3: 대분류 | B3: 항목 수 | C3: 기존 포함 | D3: SKKU 확보가능 포함 | E3: 추가 제안
A4: 학업·교과 | B4: =COUNTIF('데이터카테고리_마스터'!$J$5:$J$38,A4) -> 4 | C4: =SUMPRODUCT(--('데이터카테고리_마스터'!$J$5:$J$38=A4),--ISNUMBER(SEARCH("기존",'데이터카테고리_마스터'!$G$5:$G$38))) -> 3 | D4: =SUMPRODUCT(--('데이터카테고리_마스터'!$J$5:$J$38=A4),--ISNUMBER(SEARCH("SKKU",'데이터카테고리_마스터'!$G$5:$G$38))) -> 3 | E4: =SUMPRODUCT(--('데이터카테고리_마스터'!$J$5:$J$38=A4),--ISNUMBER(SEARCH("추가",'데이터카테고리_마스터'!$G$5:$G$38))) -> 0
A5: 학습행동(LMS) | B5: =COUNTIF('데이터카테고리_마스터'!$J$5:$J$38,A5) -> 3 | C5: =SUMPRODUCT(--('데이터카테고리_마스터'!$J$5:$J$38=A5),--ISNUMBER(SEARCH("기존",'데이터카테고리_마스터'!$G$5:$G$38))) -> 2 | D5: =SUMPRODUCT(--('데이터카테고리_마스터'!$J$5:$J$38=A5),--ISNUMBER(SEARCH("SKKU",'데이터카테고리_마스터'!$G$5:$G$38))) -> 0 | E5: =SUMPRODUCT(--('데이터카테고리_마스터'!$J$5:$J$38=A5),--ISNUMBER(SEARCH("추가",'데이터카테고리_마스터'!$G$5:$G$38))) -> 1
A6: 연구·학술 | B6: =COUNTIF('데이터카테고리_마스터'!$J$5:$J$38,A6) -> 3 | C6: =SUMPRODUCT(--('데이터카테고리_마스터'!$J$5:$J$38=A6),--ISNUMBER(SEARCH("기존",'데이터카테고리_마스터'!$G$5:$G$38))) -> 2 | D6: =SUMPRODUCT(--('데이터카테고리_마스터'!$J$5:$J$38=A6),--ISNUMBER(SEARCH("SKKU",'데이터카테고리_마스터'!$G$5:$G$38))) -> 2 | E6: =SUMPRODUCT(--('데이터카테고리_마스터'!$J$5:$J$38=A6),--ISNUMBER(SEARCH("추가",'데이터카테고리_마스터'!$G$5:$G$38))) -> 0
A7: 실무·진로 | B7: =COUNTIF('데이터카테고리_마스터'!$J$5:$J$38,A7) -> 3 | C7: =SUMPRODUCT(--('데이터카테고리_마스터'!$J$5:$J$38=A7),--ISNUMBER(SEARCH("기존",'데이터카테고리_마스터'!$G$5:$G$38))) -> 2 | D7: =SUMPRODUCT(--('데이터카테고리_마스터'!$J$5:$J$38=A7),--ISNUMBER(SEARCH("SKKU",'데이터카테고리_마스터'!$G$5:$G$38))) -> 1 | E7: =SUMPRODUCT(--('데이터카테고리_마스터'!$J$5:$J$38=A7),--ISNUMBER(SEARCH("추가",'데이터카테고리_마스터'!$G$5:$G$38))) -> 1
A8: 창의·도전 | B8: =COUNTIF('데이터카테고리_마스터'!$J$5:$J$38,A8) -> 3 | C8: =SUMPRODUCT(--('데이터카테고리_마스터'!$J$5:$J$38=A8),--ISNUMBER(SEARCH("기존",'데이터카테고리_마스터'!$G$5:$G$38))) -> 2 | D8: =SUMPRODUCT(--('데이터카테고리_마스터'!$J$5:$J$38=A8),--ISNUMBER(SEARCH("SKKU",'데이터카테고리_마스터'!$G$5:$G$38))) -> 3 | E8: =SUMPRODUCT(--('데이터카테고리_마스터'!$J$5:$J$38=A8),--ISNUMBER(SEARCH("추가",'데이터카테고리_마스터'!$G$5:$G$38))) -> 0
A9: 글로벌 | B9: =COUNTIF('데이터카테고리_마스터'!$J$5:$J$38,A9) -> 2 | C9: =SUMPRODUCT(--('데이터카테고리_마스터'!$J$5:$J$38=A9),--ISNUMBER(SEARCH("기존",'데이터카테고리_마스터'!$G$5:$G$38))) -> 1 | D9: =SUMPRODUCT(--('데이터카테고리_마스터'!$J$5:$J$38=A9),--ISNUMBER(SEARCH("SKKU",'데이터카테고리_마스터'!$G$5:$G$38))) -> 2 | E9: =SUMPRODUCT(--('데이터카테고리_마스터'!$J$5:$J$38=A9),--ISNUMBER(SEARCH("추가",'데이터카테고리_마스터'!$G$5:$G$38))) -> 0
A10: 디지털·AI | B10: =COUNTIF('데이터카테고리_마스터'!$J$5:$J$38,A10) -> 3 | C10: =SUMPRODUCT(--('데이터카테고리_마스터'!$J$5:$J$38=A10),--ISNUMBER(SEARCH("기존",'데이터카테고리_마스터'!$G$5:$G$38))) -> 2 | D10: =SUMPRODUCT(--('데이터카테고리_마스터'!$J$5:$J$38=A10),--ISNUMBER(SEARCH("SKKU",'데이터카테고리_마스터'!$G$5:$G$38))) -> 2 | E10: =SUMPRODUCT(--('데이터카테고리_마스터'!$J$5:$J$38=A10),--ISNUMBER(SEARCH("추가",'데이터카테고리_마스터'!$G$5:$G$38))) -> 0
A11: 공동체·리더십 | B11: =COUNTIF('데이터카테고리_마스터'!$J$5:$J$38,A11) -> 4 | C11: =SUMPRODUCT(--('데이터카테고리_마스터'!$J$5:$J$38=A11),--ISNUMBER(SEARCH("기존",'데이터카테고리_마스터'!$G$5:$G$38))) -> 2 | D11: =SUMPRODUCT(--('데이터카테고리_마스터'!$J$5:$J$38=A11),--ISNUMBER(SEARCH("SKKU",'데이터카테고리_마스터'!$G$5:$G$38))) -> 2 | E11: =SUMPRODUCT(--('데이터카테고리_마스터'!$J$5:$J$38=A11),--ISNUMBER(SEARCH("추가",'데이터카테고리_마스터'!$G$5:$G$38))) -> 2
A12: 자격·인증 | B12: =COUNTIF('데이터카테고리_마스터'!$J$5:$J$38,A12) -> 5 | C12: =SUMPRODUCT(--('데이터카테고리_마스터'!$J$5:$J$38=A12),--ISNUMBER(SEARCH("기존",'데이터카테고리_마스터'!$G$5:$G$38))) -> 2 | D12: =SUMPRODUCT(--('데이터카테고리_마스터'!$J$5:$J$38=A12),--ISNUMBER(SEARCH("SKKU",'데이터카테고리_마스터'!$G$5:$G$38))) -> 5 | E12: =SUMPRODUCT(--('데이터카테고리_마스터'!$J$5:$J$38=A12),--ISNUMBER(SEARCH("추가",'데이터카테고리_마스터'!$G$5:$G$38))) -> 0
A13: 진단·자기평가 | B13: =COUNTIF('데이터카테고리_마스터'!$J$5:$J$38,A13) -> 4 | C13: =SUMPRODUCT(--('데이터카테고리_마스터'!$J$5:$J$38=A13),--ISNUMBER(SEARCH("기존",'데이터카테고리_마스터'!$G$5:$G$38))) -> 0 | D13: =SUMPRODUCT(--('데이터카테고리_마스터'!$J$5:$J$38=A13),--ISNUMBER(SEARCH("SKKU",'데이터카테고리_마스터'!$G$5:$G$38))) -> 2 | E13: =SUMPRODUCT(--('데이터카테고리_마스터'!$J$5:$J$38=A13),--ISNUMBER(SEARCH("추가",'데이터카테고리_마스터'!$G$5:$G$38))) -> 2
A14: 합계 | B14: =SUM(B4:B13) -> 34 | C14: =SUM(C4:C13) -> 18 | D14: =SUM(D4:D13) -> 22 | E14: =SUM(E4:E13) -> 6
A16: ※ 숨김 열 J(대분류 라벨)를 기준으로 집계 — 마스터 시트의 B열은 병합되어 있어 별도 라벨 사용
